Workbook
Name Player: HELP_PlayersLeft!$A$2:$A$1000
Name Position: HELP_PlayersLeft!$B$2:$B$1000

Sheet HOME
A1: Fantasy Football Offline Drafter
B3: Season: | C3: 2023
B4: Version: | C4: 1.2
B5: ADP Last Updated: | C5: 28.08.2023
B7: This is a Google Sheets document to keep track of your Fantasy Football drafts. - Offline drafts with your friends - Can't or don't want to use your Fantasy platform's draft tool - Mock drafts - Whatever you want
B9: !! PLEASE READ FIRST !! You need to create a copy of this document to work with it.
B12: HOW TO USE 1) Create a copy of this document (File --> Create Copy). Downloading this document as Excel will mess with some functions. It is not advised. 2) Choose your league format and number of teams in the "Settings" tab. 3) Enter Team Names and Draft Order in the "Draft Order" tab. You do NOT need to enter team names anywhere else. Everything will be filled automatically. 4) Delete or ignore additional unnecessary draft rounds (delete rows) 5) Share your document URL with your leaguemates or display the sheet during your offline draft party. 6) Select Drafted Players in the "Draft" Tab for your selected league size. Everything else will update automatically. You can hide the other "Draft" tabs. 7) Enjoy! 8) To update to the latest document or ADP version, create a new copy from the latest version. See link below.
B15: New in Version 1.2: - Option to select the number of teams (8, 10, 12 or 14 teams) - Option to choose between Redraft (Standard, Half-PPR, PPR) and Dynasty (1QB, 2QB/SF) rankings - Bye Weeks - Bug Fixes - Improved Performance
B18: Version Check: | C18: =IFERROR(__xludf.DUMMYFUNCTION("IF(IMPORTRANGE(""https://docs.google.com/spreadsheets/d/1gsBtjhuYYhW7fpC0MdrSoM-8x0w5zndM1rr-M-FLa9c/edit#gid=0"",""VersionCheck!B5"")=C4,""YOUR DOCUMENT VERSION IS UP TO DATE"",""NEW DOCUMENT VERSION AVAILABLE"")"),"NEW DOCUMENT VERSION AVAILABLE") -> NEW DOCUMENT VERSION AVAILABLE
B19: ADP Check: | C19: =IFERROR(__xludf.DUMMYFUNCTION("IF(IMPORTRANGE(""https://docs.google.com/spreadsheets/d/1d4z9AxSQnJpejox7fbTfa7ArXQ6X_80pn45rZKeLPMs/edit?usp=sharing"",""Home!C5"")=C5,""YOUR ADPs ARE UP TO DATE"",""NEW ADPs AVAILABLE"")"),"YOUR ADPs ARE UP TO DATE") -> YOUR ADPs ARE UP TO DATE
B20: Latest version: | C20: =IFERROR(__xludf.DUMMYFUNCTION("IMPORTRANGE(""https://docs.google.com/spreadsheets/d/1gsBtjhuYYhW7fpC0MdrSoM-8x0w5zndM1rr-M-FLa9c/edit#gid=0"",""VersionCheck!C5"")"),"https://docs.google.com/spreadsheets/d/1Wf2nrjGo4AQFKorb-gXA_c7V1V-vp1N-ehazda6UBqc") -> https://docs.google.com/spreadsheets/d/1Wf2nrjGo4AQFKorb-gXA_c7V1V-vp1N-ehazda6UBqc
B22: All versions: | C22: https://docs.google.com/spreadsheets/d/1gsBtjhuYYhW7fpC0MdrSoM-8x0w5zndM1rr-M-FLa9c
B25: I would love to receive some feedback via this Google form (1 minute)
B26: https://forms.gle/6FjbktP7ZeMaTDKM8
A29: Created By
A30: Jonas Eble
A31: Discord: OpenSesame#0084
A32: Twitter: @j1eble
A33: Please tell me about any bugs, problems or your wishes for future versions.
A34: Feel free to contact me for any special or individual version of this document.

Sheet Settings
B1: Settings
B3: League | F3: Positions
B5: # of Teams | C5: 14 | F5: TRUE | G5: QB
B6: ADP Rankings | C6: Dynasty | F6: TRUE | G6: RB
B7: Scoring | C7: Half-PPR | D7: (Redraft only) | F7: TRUE | G7: WR
B8: QB Settings | C8: 2QB/SF | D8: (Dynasty only) | F8: TRUE | G8: TE
F9: TRUE | G9: K
F10: TRUE | G10: D/ST
F11: FALSE | G11: DL
F12: FALSE | G12: LB
F13: FALSE | G13: DB

Sheet Teams & Draft Order
B1: Teams & Draft Order
B2: =Settings!C5 -> 14
B3: Select Draft Order: | F3: Teams
G4: =IF(ISBLANK(G6),"ENTER TEAMS HERE FIRST","")
B5: # | C5: Team Name | G5: Team Name | H5: Owner
B6: 1. | C6: Sleeper Cell | F6: 1 | G6: Sleeper Cell
B7: 2. | C7: Phantasm | F7: 2 | G7: Phantasm
B8: 3. | C8: Icelanders | F8: 3 | G8: Icelanders
B9: 4. | C9: El Nino | F9: 4 | G9: El Nino
B10: 5. | C10: Buttheads | F10: 5 | G10: Buttheads
B11: 6. | C11: Big Boys Big Work | F11: 6 | G11: Big Boys Big Work
B12: 7. | C12: Turbo-Ginz | F12: 7 | G12: Turbo-Ginz
B13: 8. | C13: Luddite | F13: 8 | G13: Luddite
B14: 9. | C14: Achaians | F14: 9 | G14: Achaians
B15: 10. | C15: Daddy's Dogs | F15: 10 | G15: Daddy's Dogs
B16: 11. | C16: TDs and Beers | F16: 11 | G16: TDs and Beers
B17: 12. | C17: DD Riders | F17: 12 | G17: DD Riders
... B19: 14. | C19: Red Hammer | F19: 14 | G19: Red Hammer

Sheet Draft (8 Teams)
A1: Round | B1: Pick | C1: =IF(C2="","ENTER TEAMS FIRST","Team") -> Team | D1: =IF(C2="","SEE DRAFT ORDER TAB","Player") -> Player | E1: Team | F1: Pos | G1: Bye | I1: =IFERROR(__xludf.DUMMYFUNCTION("JOIN("" | "",'Team Stats'!C$1:H$1)"),"QB | RB | WR | TE | K | D/ST") -> QB | RB | WR | TE | K | D/ST | J1: =IFERROR(__xludf.DUMMYFUNCTION("JOIN("" | "",'Team Stats'!I$1:K$1)"),"DL | LB | DB") -> DL | LB | DB | L1: ="ADP (Fantasypros, "& HOME!C5 &")" -> ADP (Fantasypros, 28.08.2023)
A2: Round 01 | B2: 1 | C2: ='Teams & Draft Order'!$C$6 -> Sleeper Cell | E2: =IFERROR(VLOOKUP($D2,PlayerDB!$F$2:$G209,2,FALSE),"") | F2: =IFERROR(VLOOKUP($D2,PlayerDB!$F$2:$H209,3,FALSE),"") | G2: =IFERROR(VLOOKUP($D2,PlayerDB!$F$2:$I209,4,FALSE),"") | I2: =IFERROR(__xludf.DUMMYFUNCTION("JOIN("" | "",'Team Stats'!C$2:H$2)"),"1 | 0 | 0 | 0 | 0 | 0") -> 1 | 0 | 0 | 0 | 0 | 0 | J2: =IFERROR(__xludf.DUMMYFUNCTION("JOIN("" | "",'Team Stats'!I$2:K$2)"),"0 | 0 | 0") -> 0 | 0 | 0 | L2: Overall | P2: QB | Q2: =COUNTIF(F:F,"QB") -> 0
B3: 2 | C3: ='Teams & Draft Order'!$C$7 -> Phantasm | E3: =IFERROR(VLOOKUP($D3,PlayerDB!$F$2:$G209,2,FALSE),"") | F3: =IFERROR(VLOOKUP($D3,PlayerDB!$F$2:$H209,3,FALSE),"") | G3: =IFERROR(VLOOKUP($D3,PlayerDB!$F$2:$I209,4,FALSE),"") | I3: =IFERROR(__xludf.DUMMYFUNCTION("JOIN("" | "",'Team Stats'!C$3:H$3)"),"0 | 0 | 0 | 0 | 0 | 0") -> 0 | 0 | 0 | 0 | 0 | 0 | J3: =IFERROR(__xludf.DUMMYFUNCTION("JOIN("" | "",'Team Stats'!I$3:K$3)"),"0 | 0 | 0") -> 0 | 0 | 0 | L3: =IFERROR(__xludf.DUMMYFUNCTION("QUERY(HELP_PlayersLeft!A2:B209, ""select A LIMIT 20"")"),"Ja'Marr Chase – CIN") -> Ja'Marr Chase – CIN | M3: =IFERROR(VLOOKUP(L3,PlayerDB!$F$2:$G209,2,FALSE),"") -> 231.2 | N3: =IFERROR(VLOOKUP($L3,PlayerDB!$F$2:$H209,3,FALSE),"") -> WR | P3: =IFERROR(__xludf.DUMMYFUNCTION("QUERY(HELP_PlayersLeft!A2:B209, ""select A where B ='QB' LIMIT 20"")"),"Lamar Jackson – BAL") -> Lamar Jackson – BAL | Q3: =IFERROR(VLOOKUP(P3,PlayerDB!$F$2:$G209,2,FALSE),"") -> 378.8
B4: 3 | C4: ='Teams & Draft Order'!$C$8 -> Icelanders | E4: =IFERROR(VLOOKUP($D4,PlayerDB!$F$2:$G209,2,FALSE),"") | F4: =IFERROR(VLOOKUP($D4,PlayerDB!$F$2:$H209,3,FALSE),"") | G4: =IFERROR(VLOOKUP($D4,PlayerDB!$F$2:$I209,4,FALSE),"") | I4: =IFERROR(__xludf.DUMMYFUNCTION("JOIN("" | "",'Team Stats'!C$4:H$4)"),"0 | 0 | 0 | 0 | 0 | 0") -> 0 | 0 | 0 | 0 | 0 | 0 | J4: =IFERROR(__xludf.DUMMYFUNCTION("JOIN("" | "",'Team Stats'!I$4:K$4)"),"0 | 0 | 0") -> 0 | 0 | 0 | L4: =IFERROR(__xludf.DUMMYFUNCTION("""COMPUTED_VALUE"""),"Lamar Jackson – BAL") -> Lamar Jackson – BAL | M4: =IFERROR(VLOOKUP(L4,PlayerDB!$F$2:$G209,2,FALSE),"") -> 378.8 | N4: =IFERROR(VLOOKUP($L4,PlayerDB!$F$2:$H209,3,FALSE),"") -> QB | P4: =IFERROR(__xludf.DUMMYFUNCTION("""COMPUTED_VALUE"""),"Josh Allen – BUF") -> Josh Allen – BUF | Q4: =IFERROR(VLOOKUP(P4,PlayerDB!$F$2:$G209,2,FALSE),"") -> 376.7
B5: 4 | C5: ='Teams & Draft Order'!$C$9 -> El Nino | E5: =IFERROR(VLOOKUP($D5,PlayerDB!$F$2:$G209,2,FALSE),"") | F5: =IFERROR(VLOOKUP($D5,PlayerDB!$F$2:$H209,3,FALSE),"") | G5: =IFERROR(VLOOKUP($D5,PlayerDB!$F$2:$I209,4,FALSE),"") | I5: =IFERROR(__xludf.DUMMYFUNCTION("JOIN("" | "",'Team Stats'!C$5:H$5)"),"0 | 0 | 0 | 0 | 0 | 0") -> 0 | 0 | 0 | 0 | 0 | 0 | J5: =IFERROR(__xludf.DUMMYFUNCTION("JOIN("" | "",'Team Stats'!I$5:K$5)"),"0 | 0 | 0") -> 0 | 0 | 0 | L5: =IFERROR(__xludf.DUMMYFUNCTION("""COMPUTED_VALUE"""),"Brock Bowers – LV") -> Brock Bowers – LV | M5: =IFERROR(VLOOKUP(L5,PlayerDB!$F$2:$G209,2,FALSE),"") -> 149.7 | N5: =IFERROR(VLOOKUP($L5,PlayerDB!$F$2:$H209,3,FALSE),"") -> TE | P5: =IFERROR(__xludf.DUMMYFUNCTION("""COMPUTED_VALUE"""),"Jalen Hurts – PHI") -> Jalen Hurts – PHI | Q5: =IFERROR(VLOOKUP(P5,PlayerDB!$F$2:$G209,2,FALSE),"") -> 356.6
B6: 5 | C6: ='Teams & Draft Order'!$C$10 -> Buttheads | E6: =IFERROR(VLOOKUP($D6,PlayerDB!$F$2:$G209,2,FALSE),"") | F6: =IFERROR(VLOOKUP($D6,PlayerDB!$F$2:$H209,3,FALSE),"") | G6: =IFERROR(VLOOKUP($D6,PlayerDB!$F$2:$I209,4,FALSE),"") | I6: =IFERROR(__xludf.DUMMYFUNCTION("JOIN("" | "",'Team Stats'!C$6:H$6)"),"0 | 0 | 0 | 0 | 0 | 0") -> 0 | 0 | 0 | 0 | 0 | 0 | J6: =IFERROR(__xludf.DUMMYFUNCTION("JOIN("" | "",'Team Stats'!I$6:K$6)"),"0 | 0 | 0") -> 0 | 0 | 0 | L6: =IFERROR(__xludf.DUMMYFUNCTION("""COMPUTED_VALUE"""),"Brandon Aubrey – DAL") -> Brandon Aubrey – DAL | M6: =IFERROR(VLOOKUP(L6,PlayerDB!$F$2:$G209,2,FALSE),"") -> 140 | N6: =IFERROR(VLOOKUP($L6,PlayerDB!$F$2:$H209,3,FALSE),"") -> K | P6: =IFERROR(__xludf.DUMMYFUNCTION("""COMPUTED_VALUE"""),"Jayden Daniels – WAS") -> Jayden Daniels – WAS | Q6: =IFERROR(VLOOKUP(P6,PlayerDB!$F$2:$G209,2,FALSE),"") -> 355.8
B7: 6 | C7: ='Teams & Draft Order'!$C$11 -> Big Boys Big Work | E7: =IFERROR(VLOOKUP($D7,PlayerDB!$F$2:$G209,2,FALSE),"") | F7: =IFERROR(VLOOKUP($D7,PlayerDB!$F$2:$H209,3,FALSE),"") | G7: =IFERROR(VLOOKUP($D7,PlayerDB!$F$2:$I209,4,FALSE),"") | I7: =IFERROR(__xludf.DUMMYFUNCTION("JOIN("" | "",'Team Stats'!C$7:H$7)"),"0 | 0 | 0 | 0 | 0 | 0") -> 0 | 0 | 0 | 0 | 0 | 0 | J7: =IFERROR(__xludf.DUMMYFUNCTION("JOIN("" | "",'Team Stats'!I$7:K$7)"),"0 | 0 | 0") -> 0 | 0 | 0 | L7: =IFERROR(__xludf.DUMMYFUNCTION("""COMPUTED_VALUE"""),"Christian McCaffrey – SF") -> Christian McCaffrey – SF | M7: =IFERROR(VLOOKUP(L7,PlayerDB!$F$2:$G209,2,FALSE),"") -> 254 | N7: =IFERROR(VLOOKUP($L7,PlayerDB!$F$2:$H209,3,FALSE),"") -> RB | P7: =IFERROR(__xludf.DUMMYFUNCTION("""COMPUTED_VALUE"""),"Joe Burrow – CIN") -> Joe Burrow – CIN | Q7: =IFERROR(VLOOKUP(P7,PlayerDB!$F$2:$G209,2,FALSE),"") -> 341.6
B8: 7 | C8: ='Teams & Draft Order'!$C$12 -> Turbo-Ginz | E8: =IFERROR(VLOOKUP($D8,PlayerDB!$F$2:$G209,2,FALSE),"") | F8: =IFERROR(VLOOKUP($D8,PlayerDB!$F$2:$H209,3,FALSE),"") | G8: =IFERROR(VLOOKUP($D8,PlayerDB!$F$2:$I209,4,FALSE),"") | I8: =IFERROR(__xludf.DUMMYFUNCTION("JOIN("" | "",'Team Stats'!C$8:H$8)"),"0 | 0 | 0 | 0 | 0 | 0") -> 0 | 0 | 0 | 0 | 0 | 0 | J8: =IFERROR(__xludf.DUMMYFUNCTION("JOIN("" | "",'Team Stats'!I$8:K$8)"),"0 | 0 | 0") -> 0 | 0 | 0 | L8: =IFERROR(__xludf.DUMMYFUNCTION("""COMPUTED_VALUE"""),"Justin Jefferson – MIN") -> Justin Jefferson – MIN | M8: =IFERROR(VLOOKUP(L8,PlayerDB!$F$2:$G209,2,FALSE),"") -> 205.2 | N8: =IFERROR(VLOOKUP($L8,PlayerDB!$F$2:$H209,3,FALSE),"") -> WR | P8: =IFERROR(__xludf.DUMMYFUNCTION("""COMPUTED_VALUE"""),"Patrick Mahomes – KC") -> Patrick Mahomes – KC | Q8: =IFERROR(VLOOKUP(P8,PlayerDB!$F$2:$G209,2,FALSE),"") -> 327.1
B9: 8 | C9: ='Teams & Draft Order'!$C$13 -> Luddite | E9: =IFERROR(VLOOKUP($D9,PlayerDB!$F$2:$G209,2,FALSE),"") | F9: =IFERROR(VLOOKUP($D9,PlayerDB!$F$2:$H209,3,FALSE),"") | G9: =IFERROR(VLOOKUP($D9,PlayerDB!$F$2:$I209,4,FALSE),"") | I9: =IFERROR(__xludf.DUMMYFUNCTION("JOIN("" | "",'Team Stats'!C$9:H$9)"),"0 | 0 | 0 | 0 | 0 | 0") -> 0 | 0 | 0 | 0 | 0 | 0 | J9: =IFERROR(__xludf.DUMMYFUNCTION("JOIN("" | "",'Team Stats'!I$9:K$9)"),"0 | 0 | 0") -> 0 | 0 | 0 | L9: =IFERROR(__xludf.DUMMYFUNCTION("""COMPUTED_VALUE"""),"Josh Allen – BUF") -> Josh Allen – BUF | M9: =IFERROR(VLOOKUP(L9,PlayerDB!$F$2:$G209,2,FALSE),"") -> 376.7 | N9: =IFERROR(VLOOKUP($L9,PlayerDB!$F$2:$H209,3,FALSE),"") -> QB | P9: =IFERROR(__xludf.DUMMYFUNCTION("""COMPUTED_VALUE"""),"Baker Mayfield – TB") -> Baker Mayfield – TB | Q9: =IFERROR(VLOOKUP(P9,PlayerDB!$F$2:$G209,2,FALSE),"") -> 321.6
A10: Round 02 | B10: 9 | C10: ='Teams & Draft Order'!$C$13 -> Luddite | E10: =IFERROR(VLOOKUP($D10,PlayerDB!$F$2:$G209,2,FALSE),"") | F10: =IFERROR(VLOOKUP($D10,PlayerDB!$F$2:$H209,3,FALSE),"") | G10: =IFERROR(VLOOKUP($D10,PlayerDB!$F$2:$I209,4,FALSE),"") | I10: =IFERROR(__xludf.DUMMYFUNCTION("JOIN("" | "",'Team Stats'!C$9:H$9)"),"0 | 0 | 0 | 0 | 0 | 0") -> 0 | 0 | 0 | 0 | 0 | 0 | J10: =IFERROR(__xludf.DUMMYFUNCTION("JOIN("" | "",#REF!)"),"#REF!") -> #REF! | L10: =IFERROR(__xludf.DUMMYFUNCTION("""COMPUTED_VALUE"""),"George Kittle – SF") -> George Kittle – SF | M10: =IFERROR(VLOOKUP(L10,PlayerDB!$F$2:$G209,2,FALSE),"") -> 147.6 | N10: =IFERROR(VLOOKUP($L10,PlayerDB!$F$2:$H209,3,FALSE),"") -> TE | P10: =IFERROR(__xludf.DUMMYFUNCTION("""COMPUTED_VALUE"""),"Kyler Murray – ARI") -> Kyler Murray – ARI | Q10: =IFERROR(VLOOKUP(P10,PlayerDB!$F$2:$G209,2,FALSE),"") -> 319
B11: 10 | C11: ='Teams & Draft Order'!$C$12 -> Turbo-Ginz | E11: =IFERROR(VLOOKUP($D11,PlayerDB!$F$2:$G209,2,FALSE),"") | F11: =IFERROR(VLOOKUP($D11,PlayerDB!$F$2:$H209,3,FALSE),"") | G11: =IFERROR(VLOOKUP($D11,PlayerDB!$F$2:$I209,4,FALSE),"") | I11: =IFERROR(__xludf.DUMMYFUNCTION("JOIN("" | "",'Team Stats'!C$8:H$8)"),"0 | 0 | 0 | 0 | 0 | 0") -> 0 | 0 | 0 | 0 | 0 | 0 | J11: =IFERROR(__xludf.DUMMYFUNCTION("JOIN("" | "",#REF!)"),"#REF!") -> #REF! | L11: =IFERROR(__xludf.DUMMYFUNCTION("""COMPUTED_VALUE"""),"Chase McLaughlin – TB") -> Chase McLaughlin – TB | M11: =IFERROR(VLOOKUP(L11,PlayerDB!$F$2:$G209,2,FALSE),"") -> 136 | N11: =IFERROR(VLOOKUP($L11,PlayerDB!$F$2:$H209,3,FALSE),"") -> K | P11: =IFERROR(__xludf.DUMMYFUNCTION("""COMPUTED_VALUE"""),"Brock Purdy – SF") -> Brock Purdy – SF | Q11: =IFERROR(VLOOKUP(P11,PlayerDB!$F$2:$G209,2,FALSE),"") -> 309.6
B12: 11 | C12: ='Teams & Draft Order'!$C$11 -> Big Boys Big Work | E12: =IFERROR(VLOOKUP($D12,PlayerDB!$F$2:$G209,2,FALSE),"") | F12: =IFERROR(VLOOKUP($D12,PlayerDB!$F$2:$H209,3,FALSE),"") | G12: =IFERROR(VLOOKUP($D12,PlayerDB!$F$2:$I209,4,FALSE),"") | I12: =IFERROR(__xludf.DUMMYFUNCTION("JOIN("" | "",'Team Stats'!C$7:H$7)"),"0 | 0 | 0 | 0 | 0 | 0") -> 0 | 0 | 0 | 0 | 0 | 0 | J12: =IFERROR(__xludf.DUMMYFUNCTION("JOIN("" | "",#REF!)"),"#REF!") -> #REF! | L12: =IFERROR(__xludf.DUMMYFUNCTION("""COMPUTED_VALUE"""),"Derrick Henry – BAL") -> Derrick Henry – BAL | M12: =IFERROR(VLOOKUP(L12,PlayerDB!$F$2:$G209,2,FALSE),"") -> 253 | N12: =IFERROR(VLOOKUP($L12,PlayerDB!$F$2:$H209,3,FALSE),"") -> RB | P12: =IFERROR(__xludf.DUMMYFUNCTION("""COMPUTED_VALUE"""),"Bo Nix – DEN") -> Bo Nix – DEN | Q12: =IFERROR(VLOOKUP(P12,PlayerDB!$F$2:$G209,2,FALSE),"") -> 308.8
B13: 12 | C13: ='Teams & Draft Order'!$C$10 -> Buttheads | E13: =IFERROR(VLOOKUP($D13,PlayerDB!$F$2:$G209,2,FALSE),"") | F13: =IFERROR(VLOOKUP($D13,PlayerDB!$F$2:$H209,3,FALSE),"") | G13: =IFERROR(VLOOKUP($D13,PlayerDB!$F$2:$I209,4,FALSE),"") | I13: =IFERROR(__xludf.DUMMYFUNCTION("JOIN("" | "",'Team Stats'!C$6:H$6)"),"0 | 0 | 0 | 0 | 0 | 0") -> 0 | 0 | 0 | 0 | 0 | 0 | J13: =IFERROR(__xludf.DUMMYFUNCTION("JOIN("" | "",#REF!)"),"#REF!") -> #REF! | L13: =IFERROR(__xludf.DUMMYFUNCTION("""COMPUTED_VALUE"""),"CeeDee Lamb – DAL") -> CeeDee Lamb – DAL | M13: =IFERROR(VLOOKUP(L13,PlayerDB!$F$2:$G209,2,FALSE),"") -> 193 | N13: =IFERROR(VLOOKUP($L13,PlayerDB!$F$2:$H209,3,FALSE),"") -> WR | P13: =IFERROR(__xludf.DUMMYFUNCTION("""COMPUTED_VALUE"""),"Justin Fields – NYJ") -> Justin Fields – NYJ | Q13: =IFERROR(VLOOKUP(P13,PlayerDB!$F$2:$G209,2,FALSE),"") -> 300.9
B14: 13 | C14: ='Teams & Draft Order'!$C$9 -> El Nino | E14: =IFERROR(VLOOKUP($D14,PlayerDB!$F$2:$G209,2,FALSE),"") | F14: =IFERROR(VLOOKUP($D14,PlayerDB!$F$2:$H209,3,FALSE),"") | G14: =IFERROR(VLOOKUP($D14,PlayerDB!$F$2:$I209,4,FALSE),"") | I14: =IFERROR(__xludf.DUMMYFUNCTION("JOIN("" | "",'Team Stats'!C$5:H$5)"),"0 | 0 | 0 | 0 | 0 | 0") -> 0 | 0 | 0 | 0 | 0 | 0 | J14: =IFERROR(__xludf.DUMMYFUNCTION("JOIN("" | "",#REF!)"),"#REF!") -> #REF! | L14: =IFERROR(__xludf.DUMMYFUNCTION("""COMPUTED_VALUE"""),"Jalen Hurts – PHI") -> Jalen Hurts – PHI | M14: =IFERROR(VLOOKUP(L14,PlayerDB!$F$2:$G209,2,FALSE),"") -> 356.6 | N14: =IFERROR(VLOOKUP($L14,PlayerDB!$F$2:$H209,3,FALSE),"") -> QB | P14: =IFERROR(__xludf.DUMMYFUNCTION("""COMPUTED_VALUE"""),"Justin Herbert – LAC") -> Justin Herbert – LAC | Q14: =IFERROR(VLOOKUP(P14,PlayerDB!$F$2:$G209,2,FALSE),"") -> 293.8
B15: 14 | C15: ='Teams & Draft Order'!$C$8 -> Icelanders | E15: =IFERROR(VLOOKUP($D15,PlayerDB!$F$2:$G209,2,FALSE),"") | F15: =IFERROR(VLOOKUP($D15,PlayerDB!$F$2:$H209,3,FALSE),"") | G15: =IFERROR(VLOOKUP($D15,PlayerDB!$F$2:$I209,4,FALSE),"") | I15: =IFERROR(__xludf.DUMMYFUNCTION("JOIN("" | "",'Team Stats'!C$4:H$4)"),"0 | 0 | 0 | 0 | 0 | 0") -> 0 | 0 | 0 | 0 | 0 | 0 | J15: =IFERROR(__xludf.DUMMYFUNCTION("JOIN("" | "",#REF!)"),"#REF!") -> #REF! | L15: =IFERROR(__xludf.DUMMYFUNCTION("""COMPUTED_VALUE"""),"Trey McBride – ARI") -> Trey McBride – ARI | M15: =IFERROR(VLOOKUP(L15,PlayerDB!$F$2:$G209,2,FALSE),"") -> 139.4 | N15: =IFERROR(VLOOKUP($L15,PlayerDB!$F$2:$H209,3,FALSE),"") -> TE | P15: =IFERROR(__xludf.DUMMYFUNCTION("""COMPUTED_VALUE"""),"Jared Goff – DET") -> Jared Goff – DET | Q15: =IFERROR(VLOOKUP(P15,PlayerDB!$F$2:$G209,2,FALSE),"") -> 290
B16: 15 | C16: ='Teams & Draft Order'!$C$7 -> Phantasm | E16: =IFERROR(VLOOKUP($D16,PlayerDB!$F$2:$G209,2,FALSE),"") | F16: =IFERROR(VLOOKUP($D16,PlayerDB!$F$2:$H209,3,FALSE),"") | G16: =IFERROR(VLOOKUP($D16,PlayerDB!$F$2:$I209,4,FALSE),"") | I16: =IFERROR(__xludf.DUMMYFUNCTION("JOIN("" | "",'Team Stats'!C$3:H$3)"),"0 | 0 | 0 | 0 | 0 | 0") -> 0 | 0 | 0 | 0 | 0 | 0 | J16: =IFERROR(__xludf.DUMMYFUNCTION("JOIN("" | "",#REF!)"),"#REF!") -> #REF! | L16: =IFERROR(__xludf.DUMMYFUNCTION("""COMPUTED_VALUE"""),"Cameron Dicker – LAC") -> Cameron Dicker – LAC | M16: =IFERROR(VLOOKUP(L16,PlayerDB!$F$2:$G209,2,FALSE),"") -> 135 | N16: =IFERROR(VLOOKUP($L16,PlayerDB!$F$2:$H209,3,FALSE),"") -> K | P16: =IFERROR(__xludf.DUMMYFUNCTION("""COMPUTED_VALUE"""),"Dak Prescott – DAL") -> Dak Prescott – DAL | Q16: =IFERROR(VLOOKUP(P16,PlayerDB!$F$2:$G209,2,FALSE),"") -> 290
B17: 16 | C17: ='Teams & Draft Order'!$C$6 -> Sleeper Cell | E17: =IFERROR(VLOOKUP($D17,PlayerDB!$F$2:$G209,2,FALSE),"") | F17: =IFERROR(VLOOKUP($D17,PlayerDB!$F$2:$H209,3,FALSE),"") | G17: =IFERROR(VLOOKUP($D17,PlayerDB!$F$2:$I209,4,FALSE),"") | I17: =IFERROR(__xludf.DUMMYFUNCTION("JOIN("" | "",'Team Stats'!C$2:H$2)"),"1 | 0 | 0 | 0 | 0 | 0") -> 1 | 0 | 0 | 0 | 0 | 0 | J17: =IFERROR(__xludf.DUMMYFUNCTION("JOIN("" | "",#REF!)"),"#REF!") -> #REF! | L17: =IFERROR(__xludf.DUMMYFUNCTION("""COMPUTED_VALUE"""),"Saquon Barkley – PHI") -> Saquon Barkley – PHI | M17: =IFERROR(VLOOKUP(L17,PlayerDB!$F$2:$G209,2,FALSE),"") -> 231 | N17: =IFERROR(VLOOKUP($L17,PlayerDB!$F$2:$H209,3,FALSE),"") -> RB | P17: =IFERROR(__xludf.DUMMYFUNCTION("""COMPUTED_VALUE"""),"J.J. McCarthy – MIN") -> J.J. McCarthy – MIN | Q17: =IFERROR(VLOOKUP(P17,PlayerDB!$F$2:$G209,2,FALSE),"") -> 289.2
A18: Round 03 | B18: 17 | C18: ='Teams & Draft Order'!$C$6 -> Sleeper Cell | E18: =IFERROR(VLOOKUP($D18,PlayerDB!$F$2:$G209,2,FALSE),"") | F18: =IFERROR(VLOOKUP($D18,PlayerDB!$F$2:$H209,3,FALSE),"") | G18: =IFERROR(VLOOKUP($D18,PlayerDB!$F$2:$I209,4,FALSE),"") | I18: =IFERROR(__xludf.DUMMYFUNCTION("JOIN("" | "",'Team Stats'!C$2:H$2)"),"1 | 0 | 0 | 0 | 0 | 0") -> 1 | 0 | 0 | 0 | 0 | 0 | J18: =IFERROR(__xludf.DUMMYFUNCTION("JOIN("" | "",'Team Stats'!I$9:K$9)"),"0 | 0 | 0") -> 0 | 0 | 0 | L18: =IFERROR(__xludf.DUMMYFUNCTION("""COMPUTED_VALUE"""),"Puka Nacua – LAR") -> Puka Nacua – LAR | M18: =IFERROR(VLOOKUP(L18,PlayerDB!$F$2:$G209,2,FALSE),"") -> 187.7 | N18: =IFERROR(VLOOKUP($L18,PlayerDB!$F$2:$H209,3,FALSE),"") -> WR | P18: =IFERROR(__xludf.DUMMYFUNCTION("""COMPUTED_VALUE"""),"Caleb Williams – CHI") -> Caleb Williams – CHI | Q18: =IFERROR(VLOOKUP(P18,PlayerDB!$F$2:$G209,2,FALSE),"") -> 287.5
B19: 18 | C19: ='Teams & Draft Order'!$C$7 -> Phantasm | E19: =IFERROR(VLOOKUP($D19,PlayerDB!$F$2:$G209,2,FALSE),"") | F19: =IFERROR(VLOOKUP($D19,PlayerDB!$F$2:$H209,3,FALSE),"") | G19: =IFERROR(VLOOKUP($D19,PlayerDB!$F$2:$I209,4,FALSE),"") | I19: =IFERROR(__xludf.DUMMYFUNCTION("JOIN("" | "",'Team Stats'!C$3:H$3)"),"0 | 0 | 0 | 0 | 0 | 0") -> 0 | 0 | 0 | 0 | 0 | 0 | J19: =IFERROR(__xludf.DUMMYFUNCTION("JOIN("" | "",'Team Stats'!I$8:K$8)"),"0 | 0 | 0") -> 0 | 0 | 0 | L19: =IFERROR(__xludf.DUMMYFUNCTION("""COMPUTED_VALUE"""),"Jayden Daniels – WAS") -> Jayden Daniels – WAS | M19: =IFERROR(VLOOKUP(L19,PlayerDB!$F$2:$G209,2,FALSE),"") -> 355.8 | N19: =IFERROR(VLOOKUP($L19,PlayerDB!$F$2:$H209,3,FALSE),"") -> QB | P19: =IFERROR(__xludf.DUMMYFUNCTION("""COMPUTED_VALUE"""),"C.J. Stroud – HOU") -> C.J. Stroud – HOU | Q19: =IFERROR(VLOOKUP(P19,PlayerDB!$F$2:$G209,2,FALSE),"") -> 279.8
B20: 19 | C20: ='Teams & Draft Order'!$C$8 -> Icelanders | E20: =IFERROR(VLOOKUP($D20,PlayerDB!$F$2:$G209,2,FALSE),"") | F20: =IFERROR(VLOOKUP($D20,PlayerDB!$F$2:$H209,3,FALSE),"") | G20: =IFERROR(VLOOKUP($D20,PlayerDB!$F$2:$I209,4,FALSE),"") | I20: =IFERROR(__xludf.DUMMYFUNCTION("JOIN("" | "",'Team Stats'!C$4:H$4)"),"0 | 0 | 0 | 0 | 0 | 0") -> 0 | 0 | 0 | 0 | 0 | 0 | J20: =IFERROR(__xludf.DUMMYFUNCTION("JOIN("" | "",'Team Stats'!I$7:K$7)"),"0 | 0 | 0") -> 0 | 0 | 0 | L20: =IFERROR(__xludf.DUMMYFUNCTION("""COMPUTED_VALUE"""),"Mark Andrews – BAL") -> Mark Andrews – BAL | M20: =IFERROR(VLOOKUP(L20,PlayerDB!$F$2:$G209,2,FALSE),"") -> 117.3 | N20: =IFERROR(VLOOKUP($L20,PlayerDB!$F$2:$H209,3,FALSE),"") -> TE | P20: =IFERROR(__xludf.DUMMYFUNCTION("""COMPUTED_VALUE"""),"Jordan Love – GB") -> Jordan Love – GB | Q20: =IFERROR(VLOOKUP(P20,PlayerDB!$F$2:$G209,2,FALSE),"") -> 278.7
B21: 20 | C21: ='Teams & Draft Order'!$C$9 -> El Nino | E21: =IFERROR(VLOOKUP($D21,PlayerDB!$F$2:$G209,2,FALSE),"") | F21: =IFERROR(VLOOKUP($D21,PlayerDB!$F$2:$H209,3,FALSE),"") | G21: =IFERROR(VLOOKUP($D21,PlayerDB!$F$2:$I209,4,FALSE),"") | I21: =IFERROR(__xludf.DUMMYFUNCTION("JOIN("" | "",'Team Stats'!C$5:H$5)"),"0 | 0 | 0 | 0 | 0 | 0") -> 0 | 0 | 0 | 0 | 0 | 0 | J21: =IFERROR(__xludf.DUMMYFUNCTION("JOIN("" | "",'Team Stats'!I$6:K$6)"),"0 | 0 | 0") -> 0 | 0 | 0 | L21: =IFERROR(__xludf.DUMMYFUNCTION("""COMPUTED_VALUE"""),"Jake Elliott – PHI") -> Jake Elliott – PHI | M21: =IFERROR(VLOOKUP(L21,PlayerDB!$F$2:$G209,2,FALSE),"") -> 134 | N21: =IFERROR(VLOOKUP($L21,PlayerDB!$F$2:$H209,3,FALSE),"") -> K | P21: =IFERROR(__xludf.DUMMYFUNCTION("""COMPUTED_VALUE"""),"Trevor Lawrence – JAX") -> Trevor Lawrence – JAX | Q21: =IFERROR(VLOOKUP(P21,PlayerDB!$F$2:$G209,2,FALSE),"") -> 273.8
B22: 21 | C22: ='Teams & Draft Order'!$C$10 -> Buttheads | E22: =IFERROR(VLOOKUP($D22,PlayerDB!$F$2:$G209,2,FALSE),"") | F22: =IFERROR(VLOOKUP($D22,PlayerDB!$F$2:$H209,3,FALSE),"") | G22: =IFERROR(VLOOKUP($D22,PlayerDB!$F$2:$I209,4,FALSE),"") | I22: =IFERROR(__xludf.DUMMYFUNCTION("JOIN("" | "",'Team Stats'!C$6:H$6)"),"0 | 0 | 0 | 0 | 0 | 0") -> 0 | 0 | 0 | 0 | 0 | 0 | J22: =IFERROR(__xludf.DUMMYFUNCTION("JOIN("" | "",'Team Stats'!I$5:K$5)"),"0 | 0 | 0") -> 0 | 0 | 0 | L22: =IFERROR(__xludf.DUMMYFUNCTION("""COMPUTED_VALUE"""),"Jahmyr Gibbs – DET") -> Jahmyr Gibbs – DET | M22: =IFERROR(VLOOKUP(L22,PlayerDB!$F$2:$G209,2,FALSE),"") -> 244 | N22: =IFERROR(VLOOKUP($L22,PlayerDB!$F$2:$H209,3,FALSE),"") -> RB | P22: =IFERROR(__xludf.DUMMYFUNCTION("""COMPUTED_VALUE"""),"Drake Maye – NE") -> Drake Maye – NE | Q22: =IFERROR(VLOOKUP(P22,PlayerDB!$F$2:$G209,2,FALSE),"") -> 270.8
B23: 22 | C23: ='Teams & Draft Order'!$C$11 -> Big Boys Big Work | E23: =IFERROR(VLOOKUP($D23,PlayerDB!$F$2:$G209,2,FALSE),"") | F23: =IFERROR(VLOOKUP($D23,PlayerDB!$F$2:$H209,3,FALSE),"") | G23: =IFERROR(VLOOKUP($D23,PlayerDB!$F$2:$I209,4,FALSE),"") | I23: =IFERROR(__xludf.DUMMYFUNCTION("JOIN("" | "",'Team Stats'!C$7:H$7)"),"0 | 0 | 0 | 0 | 0 | 0") -> 0 | 0 | 0 | 0 | 0 | 0 | J23: =IFERROR(__xludf.DUMMYFUNCTION("JOIN("" | "",'Team Stats'!I$4:K$4)"),"0 | 0 | 0") -> 0 | 0 | 0
B24: 23 | C24: ='Teams & Draft Order'!$C$12 -> Turbo-Ginz | E24: =IFERROR(VLOOKUP($D24,PlayerDB!$F$2:$G209,2,FALSE),"") | F24: =IFERROR(VLOOKUP($D24,PlayerDB!$F$2:$H209,3,FALSE),"") | G24: =IFERROR(VLOOKUP($D24,PlayerDB!$F$2:$I209,4,FALSE),"") | I24: =IFERROR(__xludf.DUMMYFUNCTION("JOIN("" | "",'Team Stats'!C$8:H$8)"),"0 | 0 | 0 | 0 | 0 | 0") -> 0 | 0 | 0 | 0 | 0 | 0 | J24: =IFERROR(__xludf.DUMMYFUNCTION("JOIN("" | "",'Team Stats'!I$3:K$3)"),"0 | 0 | 0") -> 0 | 0 | 0
B25: 24 | C25: ='Teams & Draft Order'!$C$13 -> Luddite | E25: =IFERROR(VLOOKUP($D25,PlayerDB!$F$2:$G209,2,FALSE),"") | F25: =IFERROR(VLOOKUP($D25,PlayerDB!$F$2:$H209,3,FALSE),"") | G25: =IFERROR(VLOOKUP($D25,PlayerDB!$F$2:$I209,4,FALSE),"") | I25: =IFERROR(__xludf.DUMMYFUNCTION("JOIN("" | "",'Team Stats'!C$9:H$9)"),"0 | 0 | 0 | 0 | 0 | 0") -> 0 | 0 | 0 | 0 | 0 | 0 | J25: =IFERROR(__xludf.DUMMYFUNCTION("JOIN("" | "",'Team Stats'!I$2:K$2)"),"0 | 0 | 0") -> 0 | 0 | 0
A26: Round 04 | B26: 25 | C26: ='Teams & Draft Order'!$C$13 -> Luddite | E26: =IFERROR(VLOOKUP($D26,PlayerDB!$F$2:$G209,2,FALSE),"") | F26: =IFERROR(VLOOKUP($D26,PlayerDB!$F$2:$H209,3,FALSE),"") | G26: =IFERROR(VLOOKUP($D26,PlayerDB!$F$2:$I209,4,FALSE),"") | I26: =IFERROR(__xludf.DUMMYFUNCTION("JOIN("" | "",'Team Stats'!C$9:H$9)"),"0 | 0 | 0 | 0 | 0 | 0") -> 0 | 0 | 0 | 0 | 0 | 0 | J26: =IFERROR(__xludf.DUMMYFUNCTION("JOIN("" | "",'Team Stats'!I$2:K$2)"),"0 | 0 | 0") -> 0 | 0 | 0 | L26: RB | M26: =COUNTIF(F:F,"RB") -> 0 | P26: WR | Q26: =COUNTIF(F:F,"WR") -> 0
B27: 26 | C27: ='Teams & Draft Order'!$C$12 -> Turbo-Ginz | E27: =IFERROR(VLOOKUP($D27,PlayerDB!$F$2:$G209,2,FALSE),"") | F27: =IFERROR(VLOOKUP($D27,PlayerDB!$F$2:$H209,3,FALSE),"") | G27: =IFERROR(VLOOKUP($D27,PlayerDB!$F$2:$I209,4,FALSE),"") | I27: =IFERROR(__xludf.DUMMYFUNCTION("JOIN("" | "",'Team Stats'!C$8:H$8)"),"0 | 0 | 0 | 0 | 0 | 0") -> 0 | 0 | 0 | 0 | 0 | 0 | J27: =IFERROR(__xludf.DUMMYFUNCTION("JOIN("" | "",'Team Stats'!I$3:K$3)"),"0 | 0 | 0") -> 0 | 0 | 0 | L27: =IFERROR(__xludf.DUMMYFUNCTION("QUERY(HELP_PlayersLeft!A2:B209, ""select A where B ='RB' LIMIT 20"")"),"Christian McCaffrey – SF") -> Christian McCaffrey – SF | M27: =IFERROR(VLOOKUP(L27,PlayerDB!$F$2:$G209,2,FALSE),"") -> 254 | P27: =IFERROR(__xludf.DUMMYFUNCTION("QUERY(HELP_PlayersLeft!A2:B209, ""select A where B ='WR' LIMIT 20"")"),"Ja'Marr Chase – CIN") -> Ja'Marr Chase – CIN | Q27: =IFERROR(VLOOKUP(P27,PlayerDB!$F$2:$G209,2,FALSE),"") -> 231.2
B28: 27 | C28: ='Teams & Draft Order'!$C$11 -> Big Boys Big Work | E28: =IFERROR(VLOOKUP($D28,PlayerDB!$F$2:$G209,2,FALSE),"") | F28: =IFERROR(VLOOKUP($D28,PlayerDB!$F$2:$H209,3,FALSE),"") | G28: =IFERROR(VLOOKUP($D28,PlayerDB!$F$2:$I209,4,FALSE),"") | I28: =IFERROR(__xludf.DUMMYFUNCTION("JOIN("" | "",'Team Stats'!C$7:H$7)"),"0 | 0 | 0 | 0 | 0 | 0") -> 0 | 0 | 0 | 0 | 0 | 0 | J28: =IFERROR(__xludf.DUMMYFUNCTION("JOIN("" | "",'Team Stats'!I$4:K$4)"),"0 | 0 | 0") -> 0 | 0 | 0 | L28: =IFERROR(__xludf.DUMMYFUNCTION("""COMPUTED_VALUE"""),"Derrick Henry – BAL") -> Derrick Henry – BAL | M28: =IFERROR(VLOOKUP(L28,PlayerDB!$F$2:$G209,2,FALSE),"") -> 253 | P28: =IFERROR(__xludf.DUMMYFUNCTION("""COMPUTED_VALUE"""),"Justin Jefferson – MIN") -> Justin Jefferson – MIN | Q28: =IFERROR(VLOOKUP(P28,PlayerDB!$F$2:$G209,2,FALSE),"") -> 205.2
B29: 28 | C29: ='Teams & Draft Order'!$C$10 -> Buttheads | E29: =IFERROR(VLOOKUP($D29,PlayerDB!$F$2:$G209,2,FALSE),"") | F29: =IFERROR(VLOOKUP($D29,PlayerDB!$F$2:$H209,3,FALSE),"") | G29: =IFERROR(VLOOKUP($D29,PlayerDB!$F$2:$I209,4,FALSE),"") | I29: =IFERROR(__xludf.DUMMYFUNCTION("JOIN("" | "",'Team Stats'!C$6:H$6)"),"0 | 0 | 0 | 0 | 0 | 0") -> 0 | 0 | 0 | 0 | 0 | 0 | J29: =IFERROR(__xludf.DUMMYFUNCTION("JOIN("" | "",'Team Stats'!I$5:K$5)"),"0 | 0 | 0") -> 0 | 0 | 0 | L29: =IFERROR(__xludf.DUMMYFUNCTION("""COMPUTED_VALUE"""),"Saquon Barkley – PHI") -> Saquon Barkley – PHI | M29: =IFERROR(VLOOKUP(L29,PlayerDB!$F$2:$G209,2,FALSE),"") -> 231 | P29: =IFERROR(__xludf.DUMMYFUNCTION("""COMPUTED_VALUE"""),"CeeDee Lamb – DAL") -> CeeDee Lamb – DAL | Q29: =IFERROR(VLOOKUP(P29,PlayerDB!$F$2:$G209,2,FALSE),"") -> 193
B30: 29 | C30: ='Teams & Draft Order'!$C$9 -> El Nino | E30: =IFERROR(VLOOKUP($D30,PlayerDB!$F$2:$G209,2,FALSE),"") | F30: =IFERROR(VLOOKUP($D30,PlayerDB!$F$2:$H209,3,FALSE),"") | G30: =IFERROR(VLOOKUP($D30,PlayerDB!$F$2:$I209,4,FALSE),"") | I30: =IFERROR(__xludf.DUMMYFUNCTION("JOIN("" | "",'Team Stats'!C$5:H$5)"),"0 | 0 | 0 | 0 | 0 | 0") -> 0 | 0 | 0 | 0 | 0 | 0 | J30: =IFERROR(__xludf.DUMMYFUNCTION("JOIN("" | "",'Team Stats'!I$6:K$6)"),"0 | 0 | 0") -> 0 | 0 | 0 | L30: =IFERROR(__xludf.DUMMYFUNCTION("""COMPUTED_VALUE"""),"Jahmyr Gibbs – DET") -> Jahmyr Gibbs – DET | M30: =IFERROR(VLOOKUP(L30,PlayerDB!$F$2:$G209,2,FALSE),"") -> 244 | P30: =IFERROR(__xludf.DUMMYFUNCTION("""COMPUTED_VALUE"""),"Puka Nacua – LAR") -> Puka Nacua – LAR | Q30: =IFERROR(VLOOKUP(P30,PlayerDB!$F$2:$G209,2,FALSE),"") -> 187.7
B31: 30 | C31: ='Teams & Draft Order'!$C$8 -> Icelanders | E31: =IFERROR(VLOOKUP($D31,PlayerDB!$F$2:$G209,2,FALSE),"") | F31: =IFERROR(VLOOKUP($D31,PlayerDB!$F$2:$H209,3,FALSE),"") | G31: =IFERROR(VLOOKUP($D31,PlayerDB!$F$2:$I209,4,FALSE),"") | I31: =IFERROR(__xludf.DUMMYFUNCTION("JOIN("" | "",'Team Stats'!C$4:H$4)"),"0 | 0 | 0 | 0 | 0 | 0") -> 0 | 0 | 0 | 0 | 0 | 0 | J31: =IFERROR(__xludf.DUMMYFUNCTION("JOIN("" | "",'Team Stats'!I$7:K$7)"),"0 | 0 | 0") -> 0 | 0 | 0 | L31: =IFERROR(__xludf.DUMMYFUNCTION("""COMPUTED_VALUE"""),"Jonathan Taylor – IND") -> Jonathan Taylor – IND | M31: =IFERROR(VLOOKUP(L31,PlayerDB!$F$2:$G209,2,FALSE),"") -> 224 | P31: =IFERROR(__xludf.DUMMYFUNCTION("""COMPUTED_VALUE"""),"Nico Collins – HOU") -> Nico Collins – HOU | Q31: =IFERROR(VLOOKUP(P31,PlayerDB!$F$2:$G209,2,FALSE),"") -> 183.6
B32: 31 | C32: ='Teams & Draft Order'!$C$7 -> Phantasm | E32: =IFERROR(VLOOKUP($D32,PlayerDB!$F$2:$G209,2,FALSE),"") | F32: =IFERROR(VLOOKUP($D32,PlayerDB!$F$2:$H209,3,FALSE),"") | G32: =IFERROR(VLOOKUP($D32,PlayerDB!$F$2:$I209,4,FALSE),"") | I32: =IFERROR(__xludf.DUMMYFUNCTION("JOIN("" | "",'Team Stats'!C$3:H$3)"),"0 | 0 | 0 | 0 | 0 | 0") -> 0 | 0 | 0 | 0 | 0 | 0 | J32: =IFERROR(__xludf.DUMMYFUNCTION("JOIN("" | "",'Team Stats'!I$8:K$8)"),"0 | 0 | 0") -> 0 | 0 | 0 | L32: =IFERROR(__xludf.DUMMYFUNCTION("""COMPUTED_VALUE"""),"Josh Jacobs – GB") -> Josh Jacobs – GB | M32: =IFERROR(VLOOKUP(L32,PlayerDB!$F$2:$G209,2,FALSE),"") -> 224 | P32: =IFERROR(__xludf.DUMMYFUNCTION("""COMPUTED_VALUE"""),"Malik Nabers – NYG") -> Malik Nabers – NYG | Q32: =IFERROR(VLOOKUP(P32,PlayerDB!$F$2:$G209,2,FALSE),"") -> 183.3
B33: 32 | C33: ='Teams & Draft Order'!$C$6 -> Sleeper Cell | E33: =IFERROR(VLOOKUP($D33,PlayerDB!$F$2:$G209,2,FALSE),"") | F33: =IFERROR(VLOOKUP($D33,PlayerDB!$F$2:$H209,3,FALSE),"") | G33: =IFERROR(VLOOKUP($D33,PlayerDB!$F$2:$I209,4,FALSE),"") | I33: =IFERROR(__xludf.DUMMYFUNCTION("JOIN("" | "",'Team Stats'!C$2:H$2)"),"1 | 0 | 0 | 0 | 0 | 0") -> 1 | 0 | 0 | 0 | 0 | 0 | J33: =IFERROR(__xludf.DUMMYFUNCTION("JOIN("" | "",'Team Stats'!I$9:K$9)"),"0 | 0 | 0") -> 0 | 0 | 0 | L33: =IFERROR(__xludf.DUMMYFUNCTION("""COMPUTED_VALUE"""),"Ashton Jeanty – LV") -> Ashton Jeanty – LV | M33: =IFERROR(VLOOKUP(L33,PlayerDB!$F$2:$G209,2,FALSE),"") -> 222 | P33: =IFERROR(__xludf.DUMMYFUNCTION("""COMPUTED_VALUE"""),"Brian Thomas Jr. – JAX") -> Brian Thomas Jr. – JAX | Q33: =IFERROR(VLOOKUP(P33,PlayerDB!$F$2:$G209,2,FALSE),"") -> 181.4
A34: Round 05 | B34: 33 | C34: ='Teams & Draft Order'!$C$6 -> Sleeper Cell | E34: =IFERROR(VLOOKUP($D34,PlayerDB!$F$2:$G209,2,FALSE),"") | F34: =IFERROR(VLOOKUP($D34,PlayerDB!$F$2:$H209,3,FALSE),"") | G34: =IFERROR(VLOOKUP($D34,PlayerDB!$F$2:$I209,4,FALSE),"") | I34: =IFERROR(__xludf.DUMMYFUNCTION("JOIN("" | "",'Team Stats'!C$2:H$2)"),"1 | 0 | 0 | 0 | 0 | 0") -> 1 | 0 | 0 | 0 | 0 | 0 | J34: =IFERROR(__xludf.DUMMYFUNCTION("JOIN("" | "",#REF!)"),"#REF!") -> #REF! | L34: =IFERROR(__xludf.DUMMYFUNCTION("""COMPUTED_VALUE"""),"Kyren Williams – LAR") -> Kyren Williams – LAR | M34: =IFERROR(VLOOKUP(L34,PlayerDB!$F$2:$G209,2,FALSE),"") -> 215 | P34: =IFERROR(__xludf.DUMMYFUNCTION("""COMPUTED_VALUE"""),"Amon-Ra St. Brown – DET") -> Amon-Ra St. Brown – DET | Q34: =IFERROR(VLOOKUP(P34,PlayerDB!$F$2:$G209,2,FALSE),"") -> 180.8
B35: 34 | C35: ='Teams & Draft Order'!$C$7 -> Phantasm | E35: =IFERROR(VLOOKUP($D35,PlayerDB!$F$2:$G209,2,FALSE),"") | F35: =IFERROR(VLOOKUP($D35,PlayerDB!$F$2:$H209,3,FALSE),"") | G35: =IFERROR(VLOOKUP($D35,PlayerDB!$F$2:$I209,4,FALSE),"") | I35: =IFERROR(__xludf.DUMMYFUNCTION("JOIN("" | "",'Team Stats'!C$3:H$3)"),"0 | 0 | 0 | 0 | 0 | 0") -> 0 | 0 | 0 | 0 | 0 | 0 | J35: =IFERROR(__xludf.DUMMYFUNCTION("JOIN("" | "",#REF!)"),"#REF!") -> #REF! | L35: =IFERROR(__xludf.DUMMYFUNCTION("""COMPUTED_VALUE"""),"De'Von Achane – MIA") -> De'Von Achane – MIA | M35: =IFERROR(VLOOKUP(L35,PlayerDB!$F$2:$G209,2,FALSE),"") -> 212 | P35: =IFERROR(__xludf.DUMMYFUNCTION("""COMPUTED_VALUE"""),"A.J. Brown – PHI") -> A.J. Brown – PHI | Q35: =IFERROR(VLOOKUP(P35,PlayerDB!$F$2:$G209,2,FALSE),"") -> 172.8
B36: 35 | C36: ='Teams & Draft Order'!$C$8 -> Icelanders | E36: =IFERROR(VLOOKUP($D36,PlayerDB!$F$2:$G209,2,FALSE),"") | F36: =IFERROR(VLOOKUP($D36,PlayerDB!$F$2:$H209,3,FALSE),"") | G36: =IFERROR(VLOOKUP($D36,PlayerDB!$F$2:$I209,4,FALSE),"") | I36: =IFERROR(__xludf.DUMMYFUNCTION("JOIN("" | "",'Team Stats'!C$4:H$4)"),"0 | 0 | 0 | 0 | 0 | 0") -> 0 | 0 | 0 | 0 | 0 | 0 | J36: =IFERROR(__xludf.DUMMYFUNCTION("JOIN("" | "",#REF!)"),"#REF!") -> #REF! | L36: =IFERROR(__xludf.DUMMYFUNCTION("""COMPUTED_VALUE"""),"Bucky Irving – TB") -> Bucky Irving – TB | M36: =IFERROR(VLOOKUP(L36,PlayerDB!$F$2:$G209,2,FALSE),"") -> 210 | P36: =IFERROR(__xludf.DUMMYFUNCTION("""COMPUTED_VALUE"""),"Tyreek Hill – MIA") -> Tyreek Hill – MIA | Q36: =IFERROR(VLOOKUP(P36,PlayerDB!$F$2:$G209,2,FALSE),"") -> 168.5
B37: 36 | C37: ='Teams & Draft Order'!$C$9 -> El Nino | E37: =IFERROR(VLOOKUP($D37,PlayerDB!$F$2:$G209,2,FALSE),"") | F37: =IFERROR(VLOOKUP($D37,PlayerDB!$F$2:$H209,3,FALSE),"") | G37: =IFERROR(VLOOKUP($D37,PlayerDB!$F$2:$I209,4,FALSE),"") | I37: =IFERROR(__xludf.DUMMYFUNCTION("JOIN("" | "",'Team Stats'!C$5:H$5)"),"0 | 0 | 0 | 0 | 0 | 0") -> 0 | 0 | 0 | 0 | 0 | 0 | J37: =IFERROR(__xludf.DUMMYFUNCTION("JOIN("" | "",#REF!)"),"#REF!") -> #REF! | L37: =IFERROR(__xludf.DUMMYFUNCTION("""COMPUTED_VALUE"""),"James Cook – BUF") -> James Cook – BUF | M37: =IFERROR(VLOOKUP(L37,PlayerDB!$F$2:$G209,2,FALSE),"") -> 195 | P37: =IFERROR(__xludf.DUMMYFUNCTION("""COMPUTED_VALUE"""),"Drake London – ATL") -> Drake London – ATL | Q37: =IFERROR(VLOOKUP(P37,PlayerDB!$F$2:$G209,2,FALSE),"") -> 167.1
B38: 37 | C38: ='Teams & Draft Order'!$C$10 -> Buttheads | E38: =IFERROR(VLOOKUP($D38,PlayerDB!$F$2:$G209,2,FALSE),"") | F38: =IFERROR(VLOOKUP($D38,PlayerDB!$F$2:$H209,3,FALSE),"") | G38: =IFERROR(VLOOKUP($D38,PlayerDB!$F$2:$I209,4,FALSE),"") | I38: =IFERROR(__xludf.DUMMYFUNCTION("JOIN("" | "",'Team Stats'!C$6:H$6)"),"0 | 0 | 0 | 0 | 0 | 0") -> 0 | 0 | 0 | 0 | 0 | 0 | J38: =IFERROR(__xludf.DUMMYFUNCTION("JOIN("" | "",#REF!)"),"#REF!") -> #REF! | L38: =IFERROR(__xludf.DUMMYFUNCTION("""COMPUTED_VALUE"""),"Chase Brown – CIN") -> Chase Brown – CIN | M38: =IFERROR(VLOOKUP(L38,PlayerDB!$F$2:$G209,2,FALSE),"") -> 186 | P38: =IFERROR(__xludf.DUMMYFUNCTION("""COMPUTED_VALUE"""),"Ladd McConkey – LAC") -> Ladd McConkey – LAC | Q38: =IFERROR(VLOOKUP(P38,PlayerDB!$F$2:$G209,2,FALSE),"") -> 165.4
B39: 38 | C39: ='Teams & Draft Order'!$C$11 -> Big Boys Big Work | E39: =IFERROR(VLOOKUP($D39,PlayerDB!$F$2:$G209,2,FALSE),"") | F39: =IFERROR(VLOOKUP($D39,PlayerDB!$F$2:$H209,3,FALSE),"") | G39: =IFERROR(VLOOKUP($D39,PlayerDB!$F$2:$I209,4,FALSE),"") | I39: =IFERROR(__xludf.DUMMYFUNCTION("JOIN("" | "",'Team Stats'!C$7:H$7)"),"0 | 0 | 0 | 0 | 0 | 0") -> 0 | 0 | 0 | 0 | 0 | 0 | J39: =IFERROR(__xludf.DUMMYFUNCTION("JOIN("" | "",#REF!)"),"#REF!") -> #REF! | L39: =IFERROR(__xludf.DUMMYFUNCTION("""COMPUTED_VALUE"""),"Omarion Hampton – LAC") -> Omarion Hampton – LAC | M39: =IFERROR(VLOOKUP(L39,PlayerDB!$F$2:$G209,2,FALSE),"") -> 177 | P39: =IFERROR(__xludf.DUMMYFUNCTION("""COMPUTED_VALUE"""),"Mike Evans – TB") -> Mike Evans – TB | Q39: =IFERROR(VLOOKUP(P39,PlayerDB!$F$2:$G209,2,FALSE),"") -> 164.5
B40: 39 | C40: ='Teams & Draft Order'!$C$12 -> Turbo-Ginz | E40: =IFERROR(VLOOKUP($D40,PlayerDB!$F$2:$G209,2,FALSE),"") | F40: =IFERROR(VLOOKUP($D40,PlayerDB!$F$2:$H209,3,FALSE),"") | G40: =IFERROR(VLOOKUP($D40,PlayerDB!$F$2:$I209,4,FALSE),"") | I40: =IFERROR(__xludf.DUMMYFUNCTION("JOIN("" | "",'Team Stats'!C$8:H$8)"),"0 | 0 | 0 | 0 | 0 | 0") -> 0 | 0 | 0 | 0 | 0 | 0 | J40: =IFERROR(__xludf.DUMMYFUNCTION("JOIN("" | "",#REF!)"),"#REF!") -> #REF! | L40: =IFERROR(__xludf.DUMMYFUNCTION("""COMPUTED_VALUE"""),"Kenneth Walker III – SEA") -> Kenneth Walker III – SEA | M40: =IFERROR(VLOOKUP(L40,PlayerDB!$F$2:$G209,2,FALSE),"") -> 180 | P40: =IFERROR(__xludf.DUMMYFUNCTION("""COMPUTED_VALUE"""),"Tee Higgins – CIN") -> Tee Higgins – CIN | Q40: =IFERROR(VLOOKUP(P40,PlayerDB!$F$2:$G209,2,FALSE),"") -> 161.1
...

Sheet Draft (10 Teams)
A1: Round | B1: Pick | C1: =IF(C2="","ENTER TEAMS FIRST","Team") -> Team | D1: =IF(C2="","SEE DRAFT ORDER TAB","Player") -> Player | E1: Team | F1: Pos | G1: Bye | I1: =IFERROR(__xludf.DUMMYFUNCTION("JOIN("" | "",'Team Stats'!C$1:H$1)"),"QB | RB | WR | TE | K | D/ST") -> QB | RB | WR | TE | K | D/ST | J1: =IFERROR(__xludf.DUMMYFUNCTION("JOIN("" | "",'Team Stats'!I$1:K$1)"),"DL | LB | DB") -> DL | LB | DB | L1: ="ADP (Fantasypros, "& HOME!C5 &")" -> ADP (Fantasypros, 28.08.2023)
A2: Round 01 | B2: 1 | C2: ='Teams & Draft Order'!$C$6 -> Sleeper Cell | E2: =IFERROR(VLOOKUP($D2,PlayerDB!$F$2:$G261,2,FALSE),"") | F2: =IFERROR(VLOOKUP($D2,PlayerDB!$F$2:$H261,3,FALSE),"") | G2: =IFERROR(VLOOKUP($D2,PlayerDB!$F$2:$I261,4,FALSE),"") | I2: =IFERROR(__xludf.DUMMYFUNCTION("JOIN("" | "",'Team Stats'!C$2:H$2)"),"1 | 0 | 0 | 0 | 0 | 0") -> 1 | 0 | 0 | 0 | 0 | 0 | J2: =IFERROR(__xludf.DUMMYFUNCTION("JOIN("" | "",'Team Stats'!I$2:K$2)"),"0 | 0 | 0") -> 0 | 0 | 0 | L2: Overall | P2: QB | Q2: =COUNTIF(F:F,"QB") -> 0
B3: 2 | C3: ='Teams & Draft Order'!$C$7 -> Phantasm | E3: =IFERROR(VLOOKUP($D3,PlayerDB!$F$2:$G261,2,FALSE),"") | F3: =IFERROR(VLOOKUP($D3,PlayerDB!$F$2:$H261,3,FALSE),"") | G3: =IFERROR(VLOOKUP($D3,PlayerDB!$F$2:$I261,4,FALSE),"") | I3: =IFERROR(__xludf.DUMMYFUNCTION("JOIN("" | "",'Team Stats'!C$3:H$3)"),"0 | 0 | 0 | 0 | 0 | 0") -> 0 | 0 | 0 | 0 | 0 | 0 | J3: =IFERROR(__xludf.DUMMYFUNCTION("JOIN("" | "",'Team Stats'!I$3:K$3)"),"0 | 0 | 0") -> 0 | 0 | 0 | L3: =IFERROR(__xludf.DUMMYFUNCTION("QUERY(HELP_PlayersLeft!A2:B261, ""select A LIMIT 20"")"),"Ja'Marr Chase – CIN") -> Ja'Marr Chase – CIN | M3: =IFERROR(VLOOKUP(L3,PlayerDB!$F$2:$G261,2,FALSE),"") -> 231.2 | N3: =IFERROR(VLOOKUP($L3,PlayerDB!$F$2:$H261,3,FALSE),"") -> WR | P3: =IFERROR(__xludf.DUMMYFUNCTION("QUERY(HELP_PlayersLeft!A2:B261, ""select A where B ='QB' LIMIT 20"")"),"Lamar Jackson – BAL") -> Lamar Jackson – BAL | Q3: =IFERROR(VLOOKUP(P3,PlayerDB!$F$2:$G261,2,FALSE),"") -> 378.8
B4: 3 | C4: ='Teams & Draft Order'!$C$8 -> Icelanders | E4: =IFERROR(VLOOKUP($D4,PlayerDB!$F$2:$G261,2,FALSE),"") | F4: =IFERROR(VLOOKUP($D4,PlayerDB!$F$2:$H261,3,FALSE),"") | G4: =IFERROR(VLOOKUP($D4,PlayerDB!$F$2:$I261,4,FALSE),"") | I4: =IFERROR(__xludf.DUMMYFUNCTION("JOIN("" | "",'Team Stats'!C$4:H$4)"),"0 | 0 | 0 | 0 | 0 | 0") -> 0 | 0 | 0 | 0 | 0 | 0 | J4: =IFERROR(__xludf.DUMMYFUNCTION("JOIN("" | "",'Team Stats'!I$4:K$4)"),"0 | 0 | 0") -> 0 | 0 | 0 | L4: =IFERROR(__xludf.DUMMYFUNCTION("""COMPUTED_VALUE"""),"Lamar Jackson – BAL") -> Lamar Jackson – BAL | M4: =IFERROR(VLOOKUP(L4,PlayerDB!$F$2:$G261,2,FALSE),"") -> 378.8 | N4: =IFERROR(VLOOKUP($L4,PlayerDB!$F$2:$H261,3,FALSE),"") -> QB | P4: =IFERROR(__xludf.DUMMYFUNCTION("""COMPUTED_VALUE"""),"Josh Allen – BUF") -> Josh Allen – BUF | Q4: =IFERROR(VLOOKUP(P4,PlayerDB!$F$2:$G261,2,FALSE),"") -> 376.7
B5: 4 | C5: ='Teams & Draft Order'!$C$9 -> El Nino | E5: =IFERROR(VLOOKUP($D5,PlayerDB!$F$2:$G261,2,FALSE),"") | F5: =IFERROR(VLOOKUP($D5,PlayerDB!$F$2:$H261,3,FALSE),"") | G5: =IFERROR(VLOOKUP($D5,PlayerDB!$F$2:$I261,4,FALSE),"") | I5: =IFERROR(__xludf.DUMMYFUNCTION("JOIN("" | "",'Team Stats'!C$5:H$5)"),"0 | 0 | 0 | 0 | 0 | 0") -> 0 | 0 | 0 | 0 | 0 | 0 | J5: =IFERROR(__xludf.DUMMYFUNCTION("JOIN("" | "",'Team Stats'!I$5:K$5)"),"0 | 0 | 0") -> 0 | 0 | 0 | L5: =IFERROR(__xludf.DUMMYFUNCTION("""COMPUTED_VALUE"""),"Brock Bowers – LV") -> Brock Bowers – LV | M5: =IFERROR(VLOOKUP(L5,PlayerDB!$F$2:$G261,2,FALSE),"") -> 149.7 | N5: =IFERROR(VLOOKUP($L5,PlayerDB!$F$2:$H261,3,FALSE),"") -> TE | P5: =IFERROR(__xludf.DUMMYFUNCTION("""COMPUTED_VALUE"""),"Jalen Hurts – PHI") -> Jalen Hurts – PHI | Q5: =IFERROR(VLOOKUP(P5,PlayerDB!$F$2:$G261,2,FALSE),"") -> 356.6
B6: 5 | C6: ='Teams & Draft Order'!$C$10 -> Buttheads | E6: =IFERROR(VLOOKUP($D6,PlayerDB!$F$2:$G261,2,FALSE),"") | F6: =IFERROR(VLOOKUP($D6,PlayerDB!$F$2:$H261,3,FALSE),"") | G6: =IFERROR(VLOOKUP($D6,PlayerDB!$F$2:$I261,4,FALSE),"") | I6: =IFERROR(__xludf.DUMMYFUNCTION("JOIN("" | "",'Team Stats'!C$6:H$6)"),"0 | 0 | 0 | 0 | 0 | 0") -> 0 | 0 | 0 | 0 | 0 | 0 | J6: =IFERROR(__xludf.DUMMYFUNCTION("JOIN("" | "",'Team Stats'!I$6:K$6)"),"0 | 0 | 0") -> 0 | 0 | 0 | L6: =IFERROR(__xludf.DUMMYFUNCTION("""COMPUTED_VALUE"""),"Brandon Aubrey – DAL") -> Brandon Aubrey – DAL | M6: =IFERROR(VLOOKUP(L6,PlayerDB!$F$2:$G261,2,FALSE),"") -> 140 | N6: =IFERROR(VLOOKUP($L6,PlayerDB!$F$2:$H261,3,FALSE),"") -> K | P6: =IFERROR(__xludf.DUMMYFUNCTION("""COMPUTED_VALUE"""),"Jayden Daniels – WAS") -> Jayden Daniels – WAS | Q6: =IFERROR(VLOOKUP(P6,PlayerDB!$F$2:$G261,2,FALSE),"") -> 355.8
B7: 6 | C7: ='Teams & Draft Order'!$C$11 -> Big Boys Big Work | E7: =IFERROR(VLOOKUP($D7,PlayerDB!$F$2:$G261,2,FALSE),"") | F7: =IFERROR(VLOOKUP($D7,PlayerDB!$F$2:$H261,3,FALSE),"") | G7: =IFERROR(VLOOKUP($D7,PlayerDB!$F$2:$I261,4,FALSE),"") | I7: =IFERROR(__xludf.DUMMYFUNCTION("JOIN("" | "",'Team Stats'!C$7:H$7)"),"0 | 0 | 0 | 0 | 0 | 0") -> 0 | 0 | 0 | 0 | 0 | 0 | J7: =IFERROR(__xludf.DUMMYFUNCTION("JOIN("" | "",'Team Stats'!I$7:K$7)"),"0 | 0 | 0") -> 0 | 0 | 0 | L7: =IFERROR(__xludf.DUMMYFUNCTION("""COMPUTED_VALUE"""),"Christian McCaffrey – SF") -> Christian McCaffrey – SF | M7: =IFERROR(VLOOKUP(L7,PlayerDB!$F$2:$G261,2,FALSE),"") -> 254 | N7: =IFERROR(VLOOKUP($L7,PlayerDB!$F$2:$H261,3,FALSE),"") -> RB | P7: =IFERROR(__xludf.DUMMYFUNCTION("""COMPUTED_VALUE"""),"Joe Burrow – CIN") -> Joe Burrow – CIN | Q7: =IFERROR(VLOOKUP(P7,PlayerDB!$F$2:$G261,2,FALSE),"") -> 341.6
B8: 7 | C8: ='Teams & Draft Order'!$C$12 -> Turbo-Ginz | E8: =IFERROR(VLOOKUP($D8,PlayerDB!$F$2:$G261,2,FALSE),"") | F8: =IFERROR(VLOOKUP($D8,PlayerDB!$F$2:$H261,3,FALSE),"") | G8: =IFERROR(VLOOKUP($D8,PlayerDB!$F$2:$I261,4,FALSE),"") | I8: =IFERROR(__xludf.DUMMYFUNCTION("JOIN("" | "",'Team Stats'!C$8:H$8)"),"0 | 0 | 0 | 0 | 0 | 0") -> 0 | 0 | 0 | 0 | 0 | 0 | J8: =IFERROR(__xludf.DUMMYFUNCTION("JOIN("" | "",'Team Stats'!I$8:K$8)"),"0 | 0 | 0") -> 0 | 0 | 0 | L8: =IFERROR(__xludf.DUMMYFUNCTION("""COMPUTED_VALUE"""),"Justin Jefferson – MIN") -> Justin Jefferson – MIN | M8: =IFERROR(VLOOKUP(L8,PlayerDB!$F$2:$G261,2,FALSE),"") -> 205.2 | N8: =IFERROR(VLOOKUP($L8,PlayerDB!$F$2:$H261,3,FALSE),"") -> WR | P8: =IFERROR(__xludf.DUMMYFUNCTION("""COMPUTED_VALUE"""),"Patrick Mahomes – KC") -> Patrick Mahomes – KC | Q8: =IFERROR(VLOOKUP(P8,PlayerDB!$F$2:$G261,2,FALSE),"") -> 327.1
B9: 8 | C9: ='Teams & Draft Order'!$C$13 -> Luddite | E9: =IFERROR(VLOOKUP($D9,PlayerDB!$F$2:$G261,2,FALSE),"") | F9: =IFERROR(VLOOKUP($D9,PlayerDB!$F$2:$H261,3,FALSE),"") | G9: =IFERROR(VLOOKUP($D9,PlayerDB!$F$2:$I261,4,FALSE),"") | I9: =IFERROR(__xludf.DUMMYFUNCTION("JOIN("" | "",'Team Stats'!C$9:H$9)"),"0 | 0 | 0 | 0 | 0 | 0") -> 0 | 0 | 0 | 0 | 0 | 0 | J9: =IFERROR(__xludf.DUMMYFUNCTION("JOIN("" | "",'Team Stats'!I$9:K$9)"),"0 | 0 | 0") -> 0 | 0 | 0 | L9: =IFERROR(__xludf.DUMMYFUNCTION("""COMPUTED_VALUE"""),"Josh Allen – BUF") -> Josh Allen – BUF | M9: =IFERROR(VLOOKUP(L9,PlayerDB!$F$2:$G261,2,FALSE),"") -> 376.7 | N9: =IFERROR(VLOOKUP($L9,PlayerDB!$F$2:$H261,3,FALSE),"") -> QB | P9: =IFERROR(__xludf.DUMMYFUNCTION("""COMPUTED_VALUE"""),"Baker Mayfield – TB") -> Baker Mayfield – TB | Q9: =IFERROR(VLOOKUP(P9,PlayerDB!$F$2:$G261,2,FALSE),"") -> 321.6
B10: 9 | C10: ='Teams & Draft Order'!$C$14 -> Achaians | E10: =IFERROR(VLOOKUP($D10,PlayerDB!$F$2:$G261,2,FALSE),"") | F10: =IFERROR(VLOOKUP($D10,PlayerDB!$F$2:$H261,3,FALSE),"") | G10: =IFERROR(VLOOKUP($D10,PlayerDB!$F$2:$I261,4,FALSE),"") | I10: =IFERROR(__xludf.DUMMYFUNCTION("JOIN("" | "",'Team Stats'!C$10:H$10)"),"0 | 0 | 0 | 0 | 0 | 0") -> 0 | 0 | 0 | 0 | 0 | 0 | J10: =IFERROR(__xludf.DUMMYFUNCTION("JOIN("" | "",'Team Stats'!I$10:K$10)"),"0 | 0 | 0") -> 0 | 0 | 0 | L10: =IFERROR(__xludf.DUMMYFUNCTION("""COMPUTED_VALUE"""),"George Kittle – SF") -> George Kittle – SF | M10: =IFERROR(VLOOKUP(L10,PlayerDB!$F$2:$G261,2,FALSE),"") -> 147.6 | N10: =IFERROR(VLOOKUP($L10,PlayerDB!$F$2:$H261,3,FALSE),"") -> TE | P10: =IFERROR(__xludf.DUMMYFUNCTION("""COMPUTED_VALUE"""),"Kyler Murray – ARI") -> Kyler Murray – ARI | Q10: =IFERROR(VLOOKUP(P10,PlayerDB!$F$2:$G261,2,FALSE),"") -> 319
B11: 10 | C11: ='Teams & Draft Order'!$C$15 -> Daddy's Dogs | E11: =IFERROR(VLOOKUP($D11,PlayerDB!$F$2:$G261,2,FALSE),"") | F11: =IFERROR(VLOOKUP($D11,PlayerDB!$F$2:$H261,3,FALSE),"") | G11: =IFERROR(VLOOKUP($D11,PlayerDB!$F$2:$I261,4,FALSE),"") | I11: =IFERROR(__xludf.DUMMYFUNCTION("JOIN("" | "",'Team Stats'!C$11:H$11)"),"0 | 0 | 0 | 0 | 0 | 0") -> 0 | 0 | 0 | 0 | 0 | 0 | J11: =IFERROR(__xludf.DUMMYFUNCTION("JOIN("" | "",'Team Stats'!I$11:K$11)"),"0 | 0 | 0") -> 0 | 0 | 0 | L11: =IFERROR(__xludf.DUMMYFUNCTION("""COMPUTED_VALUE"""),"Chase McLaughlin – TB") -> Chase McLaughlin – TB | M11: =IFERROR(VLOOKUP(L11,PlayerDB!$F$2:$G261,2,FALSE),"") -> 136 | N11: =IFERROR(VLOOKUP($L11,PlayerDB!$F$2:$H261,3,FALSE),"") -> K | P11: =IFERROR(__xludf.DUMMYFUNCTION("""COMPUTED_VALUE"""),"Brock Purdy – SF") -> Brock Purdy – SF | Q11: =IFERROR(VLOOKUP(P11,PlayerDB!$F$2:$G261,2,FALSE),"") -> 309.6
A12: Round 02 | B12: 11 | C12: ='Teams & Draft Order'!$C$15 -> Daddy's Dogs | E12: =IFERROR(VLOOKUP($D12,PlayerDB!$F$2:$G261,2,FALSE),"") | F12: =IFERROR(VLOOKUP($D12,PlayerDB!$F$2:$H261,3,FALSE),"") | G12: =IFERROR(VLOOKUP($D12,PlayerDB!$F$2:$I261,4,FALSE),"") | I12: =IFERROR(__xludf.DUMMYFUNCTION("JOIN("" | "",'Team Stats'!C$11:H$11)"),"0 | 0 | 0 | 0 | 0 | 0") -> 0 | 0 | 0 | 0 | 0 | 0 | J12: =IFERROR(__xludf.DUMMYFUNCTION("JOIN("" | "",#REF!)"),"#REF!") -> #REF! | L12: =IFERROR(__xludf.DUMMYFUNCTION("""COMPUTED_VALUE"""),"Derrick Henry – BAL") -> Derrick Henry – BAL | M12: =IFERROR(VLOOKUP(L12,PlayerDB!$F$2:$G261,2,FALSE),"") -> 253 | N12: =IFERROR(VLOOKUP($L12,PlayerDB!$F$2:$H261,3,FALSE),"") -> RB | P12: =IFERROR(__xludf.DUMMYFUNCTION("""COMPUTED_VALUE"""),"Bo Nix – DEN") -> Bo Nix – DEN | Q12: =IFERROR(VLOOKUP(P12,PlayerDB!$F$2:$G261,2,FALSE),"") -> 308.8
B13: 12 | C13: ='Teams & Draft Order'!$C$14 -> Achaians | E13: =IFERROR(VLOOKUP($D13,PlayerDB!$F$2:$G261,2,FALSE),"") | F13: =IFERROR(VLOOKUP($D13,PlayerDB!$F$2:$H261,3,FALSE),"") | G13: =IFERROR(VLOOKUP($D13,PlayerDB!$F$2:$I261,4,FALSE),"") | I13: =IFERROR(__xludf.DUMMYFUNCTION("JOIN("" | "",'Team Stats'!C$10:H$10)"),"0 | 0 | 0 | 0 | 0 | 0") -> 0 | 0 | 0 | 0 | 0 | 0 | J13: =IFERROR(__xludf.DUMMYFUNCTION("JOIN("" | "",#REF!)"),"#REF!") -> #REF! | L13: =IFERROR(__xludf.DUMMYFUNCTION("""COMPUTED_VALUE"""),"CeeDee Lamb – DAL") -> CeeDee Lamb – DAL | M13: =IFERROR(VLOOKUP(L13,PlayerDB!$F$2:$G261,2,FALSE),"") -> 193 | N13: =IFERROR(VLOOKUP($L13,PlayerDB!$F$2:$H261,3,FALSE),"") -> WR | P13: =IFERROR(__xludf.DUMMYFUNCTION("""COMPUTED_VALUE"""),"Justin Fields – NYJ") -> Justin Fields – NYJ | Q13: =IFERROR(VLOOKUP(P13,PlayerDB!$F$2:$G261,2,FALSE),"") -> 300.9
B14: 13 | C14: ='Teams & Draft Order'!$C$13 -> Luddite | E14: =IFERROR(VLOOKUP($D14,PlayerDB!$F$2:$G261,2,FALSE),"") | F14: =IFERROR(VLOOKUP($D14,PlayerDB!$F$2:$H261,3,FALSE),"") | G14: =IFERROR(VLOOKUP($D14,PlayerDB!$F$2:$I261,4,FALSE),"") | I14: =IFERROR(__xludf.DUMMYFUNCTION("JOIN("" | "",'Team Stats'!C$9:H$9)"),"0 | 0 | 0 | 0 | 0 | 0") -> 0 | 0 | 0 | 0 | 0 | 0 | J14: =IFERROR(__xludf.DUMMYFUNCTION("JOIN("" | "",#REF!)"),"#REF!") -> #REF! | L14: =IFERROR(__xludf.DUMMYFUNCTION("""COMPUTED_VALUE"""),"Jalen Hurts – PHI") -> Jalen Hurts – PHI | M14: =IFERROR(VLOOKUP(L14,PlayerDB!$F$2:$G261,2,FALSE),"") -> 356.6 | N14: =IFERROR(VLOOKUP($L14,PlayerDB!$F$2:$H261,3,FALSE),"") -> QB | P14: =IFERROR(__xludf.DUMMYFUNCTION("""COMPUTED_VALUE"""),"Justin Herbert – LAC") -> Justin Herbert – LAC | Q14: =IFERROR(VLOOKUP(P14,PlayerDB!$F$2:$G261,2,FALSE),"") -> 293.8
B15: 14 | C15: ='Teams & Draft Order'!$C$12 -> Turbo-Ginz | E15: =IFERROR(VLOOKUP($D15,PlayerDB!$F$2:$G261,2,FALSE),"") | F15: =IFERROR(VLOOKUP($D15,PlayerDB!$F$2:$H261,3,FALSE),"") | G15: =IFERROR(VLOOKUP($D15,PlayerDB!$F$2:$I261,4,FALSE),"") | I15: =IFERROR(__xludf.DUMMYFUNCTION("JOIN("" | "",'Team Stats'!C$8:H$8)"),"0 | 0 | 0 | 0 | 0 | 0") -> 0 | 0 | 0 | 0 | 0 | 0 | J15: =IFERROR(__xludf.DUMMYFUNCTION("JOIN("" | "",#REF!)"),"#REF!") -> #REF! | L15: =IFERROR(__xludf.DUMMYFUNCTION("""COMPUTED_VALUE"""),"Trey McBride – ARI") -> Trey McBride – ARI | M15: =IFERROR(VLOOKUP(L15,PlayerDB!$F$2:$G261,2,FALSE),"") -> 139.4 | N15: =IFERROR(VLOOKUP($L15,PlayerDB!$F$2:$H261,3,FALSE),"") -> TE | P15: =IFERROR(__xludf.DUMMYFUNCTION("""COMPUTED_VALUE"""),"Jared Goff – DET") -> Jared Goff – DET | Q15: =IFERROR(VLOOKUP(P15,PlayerDB!$F$2:$G261,2,FALSE),"") -> 290
B16: 15 | C16: ='Teams & Draft Order'!$C$11 -> Big Boys Big Work | E16: =IFERROR(VLOOKUP($D16,PlayerDB!$F$2:$G261,2,FALSE),"") | F16: =IFERROR(VLOOKUP($D16,PlayerDB!$F$2:$H261,3,FALSE),"") | G16: =IFERROR(VLOOKUP($D16,PlayerDB!$F$2:$I261,4,FALSE),"") | I16: =IFERROR(__xludf.DUMMYFUNCTION("JOIN("" | "",'Team Stats'!C$7:H$7)"),"0 | 0 | 0 | 0 | 0 | 0") -> 0 | 0 | 0 | 0 | 0 | 0 | J16: =IFERROR(__xludf.DUMMYFUNCTION("JOIN("" | "",'Team Stats'!I$11:K$11)"),"0 | 0 | 0") -> 0 | 0 | 0 | L16: =IFERROR(__xludf.DUMMYFUNCTION("""COMPUTED_VALUE"""),"Cameron Dicker – LAC") -> Cameron Dicker – LAC | M16: =IFERROR(VLOOKUP(L16,PlayerDB!$F$2:$G261,2,FALSE),"") -> 135 | N16: =IFERROR(VLOOKUP($L16,PlayerDB!$F$2:$H261,3,FALSE),"") -> K | P16: =IFERROR(__xludf.DUMMYFUNCTION("""COMPUTED_VALUE"""),"Dak Prescott – DAL") -> Dak Prescott – DAL | Q16: =IFERROR(VLOOKUP(P16,PlayerDB!$F$2:$G261,2,FALSE),"") -> 290
B17: 16 | C17: ='Teams & Draft Order'!$C$10 -> Buttheads | E17: =IFERROR(VLOOKUP($D17,PlayerDB!$F$2:$G261,2,FALSE),"") | F17: =IFERROR(VLOOKUP($D17,PlayerDB!$F$2:$H261,3,FALSE),"") | G17: =IFERROR(VLOOKUP($D17,PlayerDB!$F$2:$I261,4,FALSE),"") | I17: =IFERROR(__xludf.DUMMYFUNCTION("JOIN("" | "",'Team Stats'!C$6:H$6)"),"0 | 0 | 0 | 0 | 0 | 0") -> 0 | 0 | 0 | 0 | 0 | 0 | J17: =IFERROR(__xludf.DUMMYFUNCTION("JOIN("" | "",'Team Stats'!I$10:K$10)"),"0 | 0 | 0") -> 0 | 0 | 0 | L17: =IFERROR(__xludf.DUMMYFUNCTION("""COMPUTED_VALUE"""),"Saquon Barkley – PHI") -> Saquon Barkley – PHI | M17: =IFERROR(VLOOKUP(L17,PlayerDB!$F$2:$G261,2,FALSE),"") -> 231 | N17: =IFERROR(VLOOKUP($L17,PlayerDB!$F$2:$H261,3,FALSE),"") -> RB | P17: =IFERROR(__xludf.DUMMYFUNCTION("""COMPUTED_VALUE"""),"J.J. McCarthy – MIN") -> J.J. McCarthy – MIN | Q17: =IFERROR(VLOOKUP(P17,PlayerDB!$F$2:$G261,2,FALSE),"") -> 289.2
B18: 17 | C18: ='Teams & Draft Order'!$C$9 -> El Nino | E18: =IFERROR(VLOOKUP($D18,PlayerDB!$F$2:$G261,2,FALSE),"") | F18: =IFERROR(VLOOKUP($D18,PlayerDB!$F$2:$H261,3,FALSE),"") | G18: =IFERROR(VLOOKUP($D18,PlayerDB!$F$2:$I261,4,FALSE),"") | I18: =IFERROR(__xludf.DUMMYFUNCTION("JOIN("" | "",'Team Stats'!C$5:H$5)"),"0 | 0 | 0 | 0 | 0 | 0") -> 0 | 0 | 0 | 0 | 0 | 0 | J18: =IFERROR(__xludf.DUMMYFUNCTION("JOIN("" | "",'Team Stats'!I$9:K$9)"),"0 | 0 | 0") -> 0 | 0 | 0 | L18: =IFERROR(__xludf.DUMMYFUNCTION("""COMPUTED_VALUE"""),"Puka Nacua – LAR") -> Puka Nacua – LAR | M18: =IFERROR(VLOOKUP(L18,PlayerDB!$F$2:$G261,2,FALSE),"") -> 187.7 | N18: =IFERROR(VLOOKUP($L18,PlayerDB!$F$2:$H261,3,FALSE),"") -> WR | P18: =IFERROR(__xludf.DUMMYFUNCTION("""COMPUTED_VALUE"""),"Caleb Williams – CHI") -> Caleb Williams – CHI | Q18: =IFERROR(VLOOKUP(P18,PlayerDB!$F$2:$G261,2,FALSE),"") -> 287.5
B19: 18 | C19: ='Teams & Draft Order'!$C$8 -> Icelanders | E19: =IFERROR(VLOOKUP($D19,PlayerDB!$F$2:$G261,2,FALSE),"") | F19: =IFERROR(VLOOKUP($D19,PlayerDB!$F$2:$H261,3,FALSE),"") | G19: =IFERROR(VLOOKUP($D19,PlayerDB!$F$2:$I261,4,FALSE),"") | I19: =IFERROR(__xludf.DUMMYFUNCTION("JOIN("" | "",'Team Stats'!C$4:H$4)"),"0 | 0 | 0 | 0 | 0 | 0") -> 0 | 0 | 0 | 0 | 0 | 0 | J19: =IFERROR(__xludf.DUMMYFUNCTION("JOIN("" | "",'Team Stats'!I$8:K$8)"),"0 | 0 | 0") -> 0 | 0 | 0 | L19: =IFERROR(__xludf.DUMMYFUNCTION("""COMPUTED_VALUE"""),"Jayden Daniels – WAS") -> Jayden Daniels – WAS | M19: =IFERROR(VLOOKUP(L19,PlayerDB!$F$2:$G261,2,FALSE),"") -> 355.8 | N19: =IFERROR(VLOOKUP($L19,PlayerDB!$F$2:$H261,3,FALSE),"") -> QB | P19: =IFERROR(__xludf.DUMMYFUNCTION("""COMPUTED_VALUE"""),"C.J. Stroud – HOU") -> C.J. Stroud – HOU | Q19: =IFERROR(VLOOKUP(P19,PlayerDB!$F$2:$G261,2,FALSE),"") -> 279.8
B20: 19 | C20: ='Teams & Draft Order'!$C$7 -> Phantasm | E20: =IFERROR(VLOOKUP($D20,PlayerDB!$F$2:$G261,2,FALSE),"") | F20: =IFERROR(VLOOKUP($D20,PlayerDB!$F$2:$H261,3,FALSE),"") | G20: =IFERROR(VLOOKUP($D20,PlayerDB!$F$2:$I261,4,FALSE),"") | I20: =IFERROR(__xludf.DUMMYFUNCTION("JOIN("" | "",'Team Stats'!C$3:H$3)"),"0 | 0 | 0 | 0 | 0 | 0") -> 0 | 0 | 0 | 0 | 0 | 0 | J20: =IFERROR(__xludf.DUMMYFUNCTION("JOIN("" | "",'Team Stats'!I$7:K$7)"),"0 | 0 | 0") -> 0 | 0 | 0 | L20: =IFERROR(__xludf.DUMMYFUNCTION("""COMPUTED_VALUE"""),"Mark Andrews – BAL") -> Mark Andrews – BAL | M20: =IFERROR(VLOOKUP(L20,PlayerDB!$F$2:$G261,2,FALSE),"") -> 117.3 | N20: =IFERROR(VLOOKUP($L20,PlayerDB!$F$2:$H261,3,FALSE),"") -> TE | P20: =IFERROR(__xludf.DUMMYFUNCTION("""COMPUTED_VALUE"""),"Jordan Love – GB") -> Jordan Love – GB | Q20: =IFERROR(VLOOKUP(P20,PlayerDB!$F$2:$G261,2,FALSE),"") -> 278.7
B21: 20 | C21: ='Teams & Draft Order'!$C$6 -> Sleeper Cell | E21: =IFERROR(VLOOKUP($D21,PlayerDB!$F$2:$G261,2,FALSE),"") | F21: =IFERROR(VLOOKUP($D21,PlayerDB!$F$2:$H261,3,FALSE),"") | G21: =IFERROR(VLOOKUP($D21,PlayerDB!$F$2:$I261,4,FALSE),"") | I21: =IFERROR(__xludf.DUMMYFUNCTION("JOIN("" | "",'Team Stats'!C$2:H$2)"),"1 | 0 | 0 | 0 | 0 | 0") -> 1 | 0 | 0 | 0 | 0 | 0 | J21: =IFERROR(__xludf.DUMMYFUNCTION("JOIN("" | "",'Team Stats'!I$6:K$6)"),"0 | 0 | 0") -> 0 | 0 | 0 | L21: =IFERROR(__xludf.DUMMYFUNCTION("""COMPUTED_VALUE"""),"Jake Elliott – PHI") -> Jake Elliott – PHI | M21: =IFERROR(VLOOKUP(L21,PlayerDB!$F$2:$G261,2,FALSE),"") -> 134 | N21: =IFERROR(VLOOKUP($L21,PlayerDB!$F$2:$H261,3,FALSE),"") -> K | P21: =IFERROR(__xludf.DUMMYFUNCTION("""COMPUTED_VALUE"""),"Trevor Lawrence – JAX") -> Trevor Lawrence – JAX | Q21: =IFERROR(VLOOKUP(P21,PlayerDB!$F$2:$G261,2,FALSE),"") -> 273.8
A22: Round 03 | B22: 21 | C22: ='Teams & Draft Order'!$C$6 -> Sleeper Cell | E22: =IFERROR(VLOOKUP($D22,PlayerDB!$F$2:$G261,2,FALSE),"") | F22: =IFERROR(VLOOKUP($D22,PlayerDB!$F$2:$H261,3,FALSE),"") | G22: =IFERROR(VLOOKUP($D22,PlayerDB!$F$2:$I261,4,FALSE),"") | I22: =IFERROR(__xludf.DUMMYFUNCTION("JOIN("" | "",'Team Stats'!C$2:H$2)"),"1 | 0 | 0 | 0 | 0 | 0") -> 1 | 0 | 0 | 0 | 0 | 0 | J22: =IFERROR(__xludf.DUMMYFUNCTION("JOIN("" | "",'Team Stats'!I$5:K$5)"),"0 | 0 | 0") -> 0 | 0 | 0 | L22: =IFERROR(__xludf.DUMMYFUNCTION("""COMPUTED_VALUE"""),"Jahmyr Gibbs – DET") -> Jahmyr Gibbs – DET | M22: =IFERROR(VLOOKUP(L22,PlayerDB!$F$2:$G261,2,FALSE),"") -> 244 | N22: =IFERROR(VLOOKUP($L22,PlayerDB!$F$2:$H261,3,FALSE),"") -> RB | P22: =IFERROR(__xludf.DUMMYFUNCTION("""COMPUTED_VALUE"""),"Drake Maye – NE") -> Drake Maye – NE | Q22: =IFERROR(VLOOKUP(P22,PlayerDB!$F$2:$G261,2,FALSE),"") -> 270.8
B23: 22 | C23: ='Teams & Draft Order'!$C$7 -> Phantasm | E23: =IFERROR(VLOOKUP($D23,PlayerDB!$F$2:$G261,2,FALSE),"") | F23: =IFERROR(VLOOKUP($D23,PlayerDB!$F$2:$H261,3,FALSE),"") | G23: =IFERROR(VLOOKUP($D23,PlayerDB!$F$2:$I261,4,FALSE),"") | I23: =IFERROR(__xludf.DUMMYFUNCTION("JOIN("" | "",'Team Stats'!C$3:H$3)"),"0 | 0 | 0 | 0 | 0 | 0") -> 0 | 0 | 0 | 0 | 0 | 0 | J23: =IFERROR(__xludf.DUMMYFUNCTION("JOIN("" | "",'Team Stats'!I$4:K$4)"),"0 | 0 | 0") -> 0 | 0 | 0
B24: 23 | C24: ='Teams & Draft Order'!$C$8 -> Icelanders | E24: =IFERROR(VLOOKUP($D24,PlayerDB!$F$2:$G261,2,FALSE),"") | F24: =IFERROR(VLOOKUP($D24,PlayerDB!$F$2:$H261,3,FALSE),"") | G24: =IFERROR(VLOOKUP($D24,PlayerDB!$F$2:$I261,4,FALSE),"") | I24: =IFERROR(__xludf.DUMMYFUNCTION("JOIN("" | "",'Team Stats'!C$4:H$4)"),"0 | 0 | 0 | 0 | 0 | 0") -> 0 | 0 | 0 | 0 | 0 | 0 | J24: =IFERROR(__xludf.DUMMYFUNCTION("JOIN("" | "",'Team Stats'!I$3:K$3)"),"0 | 0 | 0") -> 0 | 0 | 0
B25: 24 | C25: ='Teams & Draft Order'!$C$9 -> El Nino | E25: =IFERROR(VLOOKUP($D25,PlayerDB!$F$2:$G261,2,FALSE),"") | F25: =IFERROR(VLOOKUP($D25,PlayerDB!$F$2:$H261,3,FALSE),"") | G25: =IFERROR(VLOOKUP($D25,PlayerDB!$F$2:$I261,4,FALSE),"") | I25: =IFERROR(__xludf.DUMMYFUNCTION("JOIN("" | "",'Team Stats'!C$5:H$5)"),"0 | 0 | 0 | 0 | 0 | 0") -> 0 | 0 | 0 | 0 | 0 | 0 | J25: =IFERROR(__xludf.DUMMYFUNCTION("JOIN("" | "",'Team Stats'!I$2:K$2)"),"0 | 0 | 0") -> 0 | 0 | 0
B26: 25 | C26: ='Teams & Draft Order'!$C$10 -> Buttheads | E26: =IFERROR(VLOOKUP($D26,PlayerDB!$F$2:$G261,2,FALSE),"") | F26: =IFERROR(VLOOKUP($D26,PlayerDB!$F$2:$H261,3,FALSE),"") | G26: =IFERROR(VLOOKUP($D26,PlayerDB!$F$2:$I261,4,FALSE),"") | I26: =IFERROR(__xludf.DUMMYFUNCTION("JOIN("" | "",'Team Stats'!C$6:H$6)"),"0 | 0 | 0 | 0 | 0 | 0") -> 0 | 0 | 0 | 0 | 0 | 0 | J26: =IFERROR(__xludf.DUMMYFUNCTION("JOIN("" | "",'Team Stats'!I$2:K$2)"),"0 | 0 | 0") -> 0 | 0 | 0 | L26: RB | M26: =COUNTIF(F:F,"RB") -> 0 | P26: WR | Q26: =COUNTIF(F:F,"WR") -> 0
B27: 26 | C27: ='Teams & Draft Order'!$C$11 -> Big Boys Big Work | E27: =IFERROR(VLOOKUP($D27,PlayerDB!$F$2:$G261,2,FALSE),"") | F27: =IFERROR(VLOOKUP($D27,PlayerDB!$F$2:$H261,3,FALSE),"") | G27: =IFERROR(VLOOKUP($D27,PlayerDB!$F$2:$I261,4,FALSE),"") | I27: =IFERROR(__xludf.DUMMYFUNCTION("JOIN("" | "",'Team Stats'!C$7:H$7)"),"0 | 0 | 0 | 0 | 0 | 0") -> 0 | 0 | 0 | 0 | 0 | 0 | J27: =IFERROR(__xludf.DUMMYFUNCTION("JOIN("" | "",'Team Stats'!I$3:K$3)"),"0 | 0 | 0") -> 0 | 0 | 0 | L27: =IFERROR(__xludf.DUMMYFUNCTION("QUERY(HELP_PlayersLeft!A2:B261, ""select A where B ='RB' LIMIT 20"")"),"Christian McCaffrey – SF") -> Christian McCaffrey – SF | M27: =IFERROR(VLOOKUP(L27,PlayerDB!$F$2:$G261,2,FALSE),"") -> 254 | P27: =IFERROR(__xludf.DUMMYFUNCTION("QUERY(HELP_PlayersLeft!A2:B261, ""select A where B ='WR' LIMIT 20"")"),"Ja'Marr Chase – CIN") -> Ja'Marr Chase – CIN | Q27: =IFERROR(VLOOKUP(P27,PlayerDB!$F$2:$G261,2,FALSE),"") -> 231.2
B28: 27 | C28: ='Teams & Draft Order'!$C$12 -> Turbo-Ginz | E28: =IFERROR(VLOOKUP($D28,PlayerDB!$F$2:$G261,2,FALSE),"") | F28: =IFERROR(VLOOKUP($D28,PlayerDB!$F$2:$H261,3,FALSE),"") | G28: =IFERROR(VLOOKUP($D28,PlayerDB!$F$2:$I261,4,FALSE),"") | I28: =IFERROR(__xludf.DUMMYFUNCTION("JOIN("" | "",'Team Stats'!C$8:H$8)"),"0 | 0 | 0 | 0 | 0 | 0") -> 0 | 0 | 0 | 0 | 0 | 0 | J28: =IFERROR(__xludf.DUMMYFUNCTION("JOIN("" | "",'Team Stats'!I$4:K$4)"),"0 | 0 | 0") -> 0 | 0 | 0 | L28: =IFERROR(__xludf.DUMMYFUNCTION("""COMPUTED_VALUE"""),"Derrick Henry – BAL") -> Derrick Henry – BAL | M28: =IFERROR(VLOOKUP(L28,PlayerDB!$F$2:$G261,2,FALSE),"") -> 253 | P28: =IFERROR(__xludf.DUMMYFUNCTION("""COMPUTED_VALUE"""),"Justin Jefferson – MIN") -> Justin Jefferson – MIN | Q28: =IFERROR(VLOOKUP(P28,PlayerDB!$F$2:$G261,2,FALSE),"") -> 205.2
B29: 28 | C29: ='Teams & Draft Order'!$C$13 -> Luddite | E29: =IFERROR(VLOOKUP($D29,PlayerDB!$F$2:$G261,2,FALSE),"") | F29: =IFERROR(VLOOKUP($D29,PlayerDB!$F$2:$H261,3,FALSE),"") | G29: =IFERROR(VLOOKUP($D29,PlayerDB!$F$2:$I261,4,FALSE),"") | I29: =IFERROR(__xludf.DUMMYFUNCTION("JOIN("" | "",'Team Stats'!C$9:H$9)"),"0 | 0 | 0 | 0 | 0 | 0") -> 0 | 0 | 0 | 0 | 0 | 0 | J29: =IFERROR(__xludf.DUMMYFUNCTION("JOIN("" | "",'Team Stats'!I$5:K$5)"),"0 | 0 | 0") -> 0 | 0 | 0 | L29: =IFERROR(__xludf.DUMMYFUNCTION("""COMPUTED_VALUE"""),"Saquon Barkley – PHI") -> Saquon Barkley – PHI | M29: =IFERROR(VLOOKUP(L29,PlayerDB!$F$2:$G261,2,FALSE),"") -> 231 | P29: =IFERROR(__xludf.DUMMYFUNCTION("""COMPUTED_VALUE"""),"CeeDee Lamb – DAL") -> CeeDee Lamb – DAL | Q29: =IFERROR(VLOOKUP(P29,PlayerDB!$F$2:$G261,2,FALSE),"") -> 193
